Workbook

Sheet Clasificación
A1: CLASIFICACIÓN GENERAL · PORRA MUNDIAL 2026
A2: Puesto | B2: Jugador | C2: J1 | D2: J2 | E2: J3 | F2: 32avos | G2: 8vos | H2: 4tos | I2: Semis | J2: Final | K2: Σ Partidos | L2: Extra | M2: Bono | N2: TOTAL
A3: =RANK(N3,$N$3:$N$8) | B3: Jugador 1 | C3: =SUM('Jornada 1'!I3:I26) | D3: =SUM('Jornada 2'!I3:I26) | E3: =SUM('Jornada 3'!I3:I26) | F3: =SUM('32avos'!I3:I18) | G3: =SUM('octavos'!I3:I10) | H3: =SUM('cuartos'!I3:I6) | I3: =SUM('semis'!I3:I4) | J3: =SUM('final'!I3:I3) | K3: =SUM(C3:J3) | L3: ='Apuestas Extra'!B10 | M3: 0 | N3: =K3+L3+M3
A4: =RANK(N4,$N$3:$N$8) | B4: Jugador 2 | C4: =SUM('Jornada 1'!L3:L26) | D4: =SUM('Jornada 2'!L3:L26) | E4: =SUM('Jornada 3'!L3:L26) | F4: =SUM('32avos'!L3:L18) | G4: =SUM('octavos'!L3:L10) | H4: =SUM('cuartos'!L3:L6) | I4: =SUM('semis'!L3:L4) | J4: =SUM('final'!L3:L3) | K4: =SUM(C4:J4) | L4: ='Apuestas Extra'!B11 | M4: 0 | N4: =K4+L4+M4
A5: =RANK(N5,$N$3:$N$8) | B5: Jugador 3 | C5: =SUM('Jornada 1'!O3:O26) | D5: =SUM('Jornada 2'!O3:O26) | E5: =SUM('Jornada 3'!O3:O26) | F5: =SUM('32avos'!O3:O18) | G5: =SUM('octavos'!O3:O10) | H5: =SUM('cuartos'!O3:O6) | I5: =SUM('semis'!O3:O4) | J5: =SUM('final'!O3:O3) | K5: =SUM(C5:J5) | L5: ='Apuestas Extra'!B12 | M5: 0 | N5: =K5+L5+M5
A6: =RANK(N6,$N$3:$N$8) | B6: Jugador 4 | C6: =SUM('Jornada 1'!R3:R26) | D6: =SUM('Jornada 2'!R3:R26) | E6: =SUM('Jornada 3'!R3:R26) | F6: =SUM('32avos'!R3:R18) | G6: =SUM('octavos'!R3:R10) | H6: =SUM('cuartos'!R3:R6) | I6: =SUM('semis'!R3:R4) | J6: =SUM('final'!R3:R3) | K6: =SUM(C6:J6) | L6: ='Apuestas Extra'!B13 | M6: 0 | N6: =K6+L6+M6
A7: =RANK(N7,$N$3:$N$8) | B7: Jugador 5 | C7: =SUM('Jornada 1'!U3:U26) | D7: =SUM('Jornada 2'!U3:U26) | E7: =SUM('Jornada 3'!U3:U26) | F7: =SUM('32avos'!U3:U18) | G7: =SUM('octavos'!U3:U10) | H7: =SUM('cuartos'!U3:U6) | I7: =SUM('semis'!U3:U4) | J7: =SUM('final'!U3:U3) | K7: =SUM(C7:J7) | L7: ='Apuestas Extra'!B14 | M7: 0 | N7: =K7+L7+M7
A8: =RANK(N8,$N$3:$N$8) | B8: Jugador 6 | C8: =SUM('Jornada 1'!X3:X26) | D8: =SUM('Jornada 2'!X3:X26) | E8: =SUM('Jornada 3'!X3:X26) | F8: =SUM('32avos'!X3:X18) | G8: =SUM('octavos'!X3:X10) | H8: =SUM('cuartos'!X3:X6) | I8: =SUM('semis'!X3:X4) | J8: =SUM('final'!X3:X3) | K8: =SUM(C8:J8) | L8: ='Apuestas Extra'!B15 | M8: 30 | N8: =K8+L8+M8
A10: Estado de entregas:
A11: Jugador 1: J1, J2, J3, 32avos, octavos, cuartos, semis, final + Extra
A12: Jugador 2: J1, J2, J3, 32avos, octavos, cuartos, semis + Extra
A13: Jugador 3: J1, J2, J3, 32avos, octavos, cuartos, semis, final + Extra
A14: Jugador 4: J1, J2, J3, 32avos, octavos, cuartos, semis, final + Extra
A15: Jugador 5: J1, J2, J3, 32avos, octavos, cuartos, semis, final + Extra
A16: Jugador 6: 32avos, octavos, cuartos, semis

Sheet Jornada 1
A1: PARTIDO | E1: RESULTADO REAL | G1: Jugador 1 | J1: Jugador 2 | M1: Jugador 3 | P1: Jugador 4 | S1: Jugador 5 | V1: Jugador 6
A2: Nº | B2: Grupo | C2: LOCAL | D2: VISITANTE | E2: GL | F2: GV | G2: GL | H2: GV | I2: Pts | J2: GL | K2: GV | L2: Pts | M2: GL | N2: GV | O2: Pts | P2: GL | Q2: GV | R2: Pts | S2: GL | T2: GV | U2: Pts | V2: GL | W2: GV | X2: Pts
A3: 1 | B3: A | C3: México | D3: Sudáfrica | E3: 2 | F3: 0 | G3: 2 | H3: 1 | I3: =IF(OR($E3="",$F3=""),"",IF(OR(G3="",H3=""),"",IF(AND(G3=$E3,H3=$F3),2,IF(SIGN(G3-H3)=SIGN($E3-$F3),1,0)))) | J3: 2 | K3: 0 | L3: =IF(OR($E3="",$F3=""),"",IF(OR(J3="",K3=""),"",IF(AND(J3=$E3,K3=$F3),2,IF(SIGN(J3-K3)=SIGN($E3-$F3),1,0)))) | M3: 2 | N3: 1 | O3: =IF(OR($E3="",$F3=""),"",IF(OR(M3="",N3=""),"",IF(AND(M3=$E3,N3=$F3),2,IF(SIGN(M3-N3)=SIGN($E3-$F3),1,0)))) | P3: 1 | Q3: 1 | R3: =IF(OR($E3="",$F3=""),"",IF(OR(P3="",Q3=""),"",IF(AND(P3=$E3,Q3=$F3),2,IF(SIGN(P3-Q3)=SIGN($E3-$F3),1,0)))) | S3: 2 | T3: 1 | U3: =IF(OR($E3="",$F3=""),"",IF(OR(S3="",T3=""),"",IF(AND(S3=$E3,T3=$F3),2,IF(SIGN(S3-T3)=SIGN($E3-$F3),1,0)))) | X3: =IF(OR($E3="",$F3=""),"",IF(OR(V3="",W3=""),"",IF(AND(V3=$E3,W3=$F3),2,IF(SIGN(V3-W3)=SIGN($E3-$F3),1,0))))
A4: 2 | B4: A | C4: Corea del Sur | D4: República Checa | E4: 2 | F4: 1 | G4: 1 | H4: 1 | I4: =IF(OR($E4="",$F4=""),"",IF(OR(G4="",H4=""),"",IF(AND(G4=$E4,H4=$F4),2,IF(SIGN(G4-H4)=SIGN($E4-$F4),1,0)))) | J4: 1 | K4: 1 | L4: =IF(OR($E4="",$F4=""),"",IF(OR(J4="",K4=""),"",IF(AND(J4=$E4,K4=$F4),2,IF(SIGN(J4-K4)=SIGN($E4-$F4),1,0)))) | M4: 1 | N4: 1 | O4: =IF(OR($E4="",$F4=""),"",IF(OR(M4="",N4=""),"",IF(AND(M4=$E4,N4=$F4),2,IF(SIGN(M4-N4)=SIGN($E4-$F4),1,0)))) | P4: 0 | Q4: 1 | R4: =IF(OR($E4="",$F4=""),"",IF(OR(P4="",Q4=""),"",IF(AND(P4=$E4,Q4=$F4),2,IF(SIGN(P4-Q4)=SIGN($E4-$F4),1,0)))) | S4: 2 | T4: 1 | U4: =IF(OR($E4="",$F4=""),"",IF(OR(S4="",T4=""),"",IF(AND(S4=$E4,T4=$F4),2,IF(SIGN(S4-T4)=SIGN($E4-$F4),1,0)))) | X4: =IF(OR($E4="",$F4=""),"",IF(OR(V4="",W4=""),"",IF(AND(V4=$E4,W4=$F4),2,IF(SIGN(V4-W4)=SIGN($E4-$F4),1,0))))
A5: 3 | B5: B | C5: Canadá | D5: Bosnia y Herzegovina | E5: 1 | F5: 1 | G5: 0 | H5: 0 | I5: =IF(OR($E5="",$F5=""),"",IF(OR(G5="",H5=""),"",IF(AND(G5=$E5,H5=$F5),2,IF(SIGN(G5-H5)=SIGN($E5-$F5),1,0)))) | J5: 2 | K5: 0 | L5: =IF(OR($E5="",$F5=""),"",IF(OR(J5="",K5=""),"",IF(AND(J5=$E5,K5=$F5),2,IF(SIGN(J5-K5)=SIGN($E5-$F5),1,0)))) | M5: 2 | N5: 1 | O5: =IF(OR($E5="",$F5=""),"",IF(OR(M5="",N5=""),"",IF(AND(M5=$E5,N5=$F5),2,IF(SIGN(M5-N5)=SIGN($E5-$F5),1,0)))) | P5: 1 | Q5: 1 | R5: =IF(OR($E5="",$F5=""),"",IF(OR(P5="",Q5=""),"",IF(AND(P5=$E5,Q5=$F5),2,IF(SIGN(P5-Q5)=SIGN($E5-$F5),1,0)))) | S5: 1 | T5: 1 | U5: =IF(OR($E5="",$F5=""),"",IF(OR(S5="",T5=""),"",IF(AND(S5=$E5,T5=$F5),2,IF(SIGN(S5-T5)=SIGN($E5-$F5),1,0)))) | X5: =IF(OR($E5="",$F5=""),"",IF(OR(V5="",W5=""),"",IF(AND(V5=$E5,W5=$F5),2,IF(SIGN(V5-W5)=SIGN($E5-$F5),1,0))))
A6: 4 | B6: B | C6: Catar | D6: Suiza | E6: 1 | F6: 1 | G6: 0 | H6: 1 | I6: =IF(OR($E6="",$F6=""),"",IF(OR(G6="",H6=""),"",IF(AND(G6=$E6,H6=$F6),2,IF(SIGN(G6-H6)=SIGN($E6-$F6),1,0)))) | J6: 0 | K6: 2 | L6: =IF(OR($E6="",$F6=""),"",IF(OR(J6="",K6=""),"",IF(AND(J6=$E6,K6=$F6),2,IF(SIGN(J6-K6)=SIGN($E6-$F6),1,0)))) | M6: 0 | N6: 2 | O6: =IF(OR($E6="",$F6=""),"",IF(OR(M6="",N6=""),"",IF(AND(M6=$E6,N6=$F6),2,IF(SIGN(M6-N6)=SIGN($E6-$F6),1,0)))) | P6: 0 | Q6: 2 | R6: =IF(OR($E6="",$F6=""),"",IF(OR(P6="",Q6=""),"",IF(AND(P6=$E6,Q6=$F6),2,IF(SIGN(P6-Q6)=SIGN($E6-$F6),1,0)))) | S6: 1 | T6: 1 | U6: =IF(OR($E6="",$F6=""),"",IF(OR(S6="",T6=""),"",IF(AND(S6=$E6,T6=$F6),2,IF(SIGN(S6-T6)=SIGN($E6-$F6),1,0)))) | X6: =IF(OR($E6="",$F6=""),"",IF(OR(V6="",W6=""),"",IF(AND(V6=$E6,W6=$F6),2,IF(SIGN(V6-W6)=SIGN($E6-$F6),1,0))))
A7: 5 | B7: C | C7: Brasil | D7: Marruecos | E7: 1 | F7: 1 | G7: 1 | H7: 1 | I7: =IF(OR($E7="",$F7=""),"",IF(OR(G7="",H7=""),"",IF(AND(G7=$E7,H7=$F7),2,IF(SIGN(G7-H7)=SIGN($E7-$F7),1,0)))) | J7: 3 | K7: 1 | L7: =IF(OR($E7="",$F7=""),"",IF(OR(J7="",K7=""),"",IF(AND(J7=$E7,K7=$F7),2,IF(SIGN(J7-K7)=SIGN($E7-$F7),1,0)))) | M7: 2 | N7: 0 | O7: =IF(OR($E7="",$F7=""),"",IF(OR(M7="",N7=""),"",IF(AND(M7=$E7,N7=$F7),2,IF(SIGN(M7-N7)=SIGN($E7-$F7),1,0)))) | P7: 1 | Q7: 0 | R7: =IF(OR($E7="",$F7=""),"",IF(OR(P7="",Q7=""),"",IF(AND(P7=$E7,Q7=$F7),2,IF(SIGN(P7-Q7)=SIGN($E7-$F7),1,0)))) | S7: 3 | T7: 1 | U7: =IF(OR($E7="",$F7=""),"",IF(OR(S7="",T7=""),"",IF(AND(S7=$E7,T7=$F7),2,IF(SIGN(S7-T7)=SIGN($E7-$F7),1,0)))) | X7: =IF(OR($E7="",$F7=""),"",IF(OR(V7="",W7=""),"",IF(AND(V7=$E7,W7=$F7),2,IF(SIGN(V7-W7)=SIGN($E7-$F7),1,0))))
A8: 6 | B8: C | C8: Haití | D8: Escocia | E8: 0 | F8: 1 | G8: 1 | H8: 2 | I8: =IF(OR($E8="",$F8=""),"",IF(OR(G8="",H8=""),"",IF(AND(G8=$E8,H8=$F8),2,IF(SIGN(G8-H8)=SIGN($E8-$F8),1,0)))) | J8: 0 | K8: 4 | L8: =IF(OR($E8="",$F8=""),"",IF(OR(J8="",K8=""),"",IF(AND(J8=$E8,K8=$F8),2,IF(SIGN(J8-K8)=SIGN($E8-$F8),1,0)))) | M8: 0 | N8: 2 | O8: =IF(OR($E8="",$F8=""),"",IF(OR(M8="",N8=""),"",IF(AND(M8=$E8,N8=$F8),2,IF(SIGN(M8-N8)=SIGN($E8-$F8),1,0)))) | P8: 1 | Q8: 3 | R8: =IF(OR($E8="",$F8=""),"",IF(OR(P8="",Q8=""),"",IF(AND(P8=$E8,Q8=$F8),2,IF(SIGN(P8-Q8)=SIGN($E8-$F8),1,0)))) | S8: 0 | T8: 2 | U8: =IF(OR($E8="",$F8=""),"",IF(OR(S8="",T8=""),"",IF(AND(S8=$E8,T8=$F8),2,IF(SIGN(S8-T8)=SIGN($E8-$F8),1,0)))) | X8: =IF(OR($E8="",$F8=""),"",IF(OR(V8="",W8=""),"",IF(AND(V8=$E8,W8=$F8),2,IF(SIGN(V8-W8)=SIGN($E8-$F8),1,0))))
A9: 7 | B9: D | C9: Estados Unidos | D9: Paraguay | E9: 4 | F9: 1 | G9: 0 | H9: 0 | I9: =IF(OR($E9="",$F9=""),"",IF(OR(G9="",H9=""),"",IF(AND(G9=$E9,H9=$F9),2,IF(SIGN(G9-H9)=SIGN($E9-$F9),1,0)))) | J9: 2 | K9: 1 | L9: =IF(OR($E9="",$F9=""),"",IF(OR(J9="",K9=""),"",IF(AND(J9=$E9,K9=$F9),2,IF(SIGN(J9-K9)=SIGN($E9-$F9),1,0)))) | M9: 1 | N9: 1 | O9: =IF(OR($E9="",$F9=""),"",IF(OR(M9="",N9=""),"",IF(AND(M9=$E9,N9=$F9),2,IF(SIGN(M9-N9)=SIGN($E9-$F9),1,0)))) | P9: 1 | Q9: 2 | R9: =IF(OR($E9="",$F9=""),"",IF(OR(P9="",Q9=""),"",IF(AND(P9=$E9,Q9=$F9),2,IF(SIGN(P9-Q9)=SIGN($E9-$F9),1,0)))) | S9: 2 | T9: 1 | U9: =IF(OR($E9="",$F9=""),"",IF(OR(S9="",T9=""),"",IF(AND(S9=$E9,T9=$F9),2,IF(SIGN(S9-T9)=SIGN($E9-$F9),1,0)))) | X9: =IF(OR($E9="",$F9=""),"",IF(OR(V9="",W9=""),"",IF(AND(V9=$E9,W9=$F9),2,IF(SIGN(V9-W9)=SIGN($E9-$F9),1,0))))
A10: 8 | B10: D | C10: Australia | D10: Turquía | E10: 2 | F10: 0 | G10: 0 | H10: 2 | I10: =IF(OR($E10="",$F10=""),"",IF(OR(G10="",H10=""),"",IF(AND(G10=$E10,H10=$F10),2,IF(SIGN(G10-H10)=SIGN($E10-$F10),1,0)))) | J10: 0 | K10: 1 | L10: =IF(OR($E10="",$F10=""),"",IF(OR(J10="",K10=""),"",IF(AND(J10=$E10,K10=$F10),2,IF(SIGN(J10-K10)=SIGN($E10-$F10),1,0)))) | M10: 1 | N10: 2 | O10: =IF(OR($E10="",$F10=""),"",IF(OR(M10="",N10=""),"",IF(AND(M10=$E10,N10=$F10),2,IF(SIGN(M10-N10)=SIGN($E10-$F10),1,0)))) | P10: 0 | Q10: 3 | R10: =IF(OR($E10="",$F10=""),"",IF(OR(P10="",Q10=""),"",IF(AND(P10=$E10,Q10=$F10),2,IF(SIGN(P10-Q10)=SIGN($E10-$F10),1,0)))) | S10: 1 | T10: 2 | U10: =IF(OR($E10="",$F10=""),"",IF(OR(S10="",T10=""),"",IF(AND(S10=$E10,T10=$F10),2,IF(SIGN(S10-T10)=SIGN($E10-$F10),1,0)))) | X10: =IF(OR($E10="",$F10=""),"",IF(OR(V10="",W10=""),"",IF(AND(V10=$E10,W10=$F10),2,IF(SIGN(V10-W10)=SIGN($E10-$F10),1,0))))
A11: 9 | B11: E | C11: Alemania | D11: Curazao | E11: 7 | F11: 1 | G11: 5 | H11: 0 | I11: =IF(OR($E11="",$F11=""),"",IF(OR(G11="",H11=""),"",IF(AND(G11=$E11,H11=$F11),2,IF(SIGN(G11-H11)=SIGN($E11-$F11),1,0)))) | J11: 4 | K11: 0 | L11: =IF(OR($E11="",$F11=""),"",IF(OR(J11="",K11=""),"",IF(AND(J11=$E11,K11=$F11),2,IF(SIGN(J11-K11)=SIGN($E11-$F11),1,0)))) | M11: 3 | N11: 0 | O11: =IF(OR($E11="",$F11=""),"",IF(OR(M11="",N11=""),"",IF(AND(M11=$E11,N11=$F11),2,IF(SIGN(M11-N11)=SIGN($E11-$F11),1,0)))) | P11: 4 | Q11: 0 | R11: =IF(OR($E11="",$F11=""),"",IF(OR(P11="",Q11=""),"",IF(AND(P11=$E11,Q11=$F11),2,IF(SIGN(P11-Q11)=SIGN($E11-$F11),1,0)))) | S11: 4 | T11: 0 | U11: =IF(OR($E11="",$F11=""),"",IF(OR(S11="",T11=""),"",IF(AND(S11=$E11,T11=$F11),2,IF(SIGN(S11-T11)=SIGN($E11-$F11),1,0)))) | X11: =IF(OR($E11="",$F11=""),"",IF(OR(V11="",W11=""),"",IF(AND(V11=$E11,W11=$F11),2,IF(SIGN(V11-W11)=SIGN($E11-$F11),1,0))))
A12: 10 | B12: E | C12: Costa de Marfil | D12: Ecuador | E12: 1 | F12: 0 | G12: 1 | H12: 3 | I12: =IF(OR($E12="",$F12=""),"",IF(OR(G12="",H12=""),"",IF(AND(G12=$E12,H12=$F12),2,IF(SIGN(G12-H12)=SIGN($E12-$F12),1,0)))) | J12: 1 | K12: 1 | L12: =IF(OR($E12="",$F12=""),"",IF(OR(J12="",K12=""),"",IF(AND(J12=$E12,K12=$F12),2,IF(SIGN(J12-K12)=SIGN($E12-$F12),1,0)))) | M12: 1 | N12: 1 | O12: =IF(OR($E12="",$F12=""),"",IF(OR(M12="",N12=""),"",IF(AND(M12=$E12,N12=$F12),2,IF(SIGN(M12-N12)=SIGN($E12-$F12),1,0)))) | P12: 2 | Q12: 1 | R12: =IF(OR($E12="",$F12=""),"",IF(OR(P12="",Q12=""),"",IF(AND(P12=$E12,Q12=$F12),2,IF(SIGN(P12-Q12)=SIGN($E12-$F12),1,0)))) | S12: 1 | T12: 1 | U12: =IF(OR($E12="",$F12=""),"",IF(OR(S12="",T12=""),"",IF(AND(S12=$E12,T12=$F12),2,IF(SIGN(S12-T12)=SIGN($E12-$F12),1,0)))) | X12: =IF(OR($E12="",$F12=""),"",IF(OR(V12="",W12=""),"",IF(AND(V12=$E12,W12=$F12),2,IF(SIGN(V12-W12)=SIGN($E12-$F12),1,0))))
A13: 11 | B13: F | C13: Países Bajos | D13: Japón | E13: 2 | F13: 2 | G13: 2 | H13: 1 | I13: =IF(OR($E13="",$F13=""),"",IF(OR(G13="",H13=""),"",IF(AND(G13=$E13,H13=$F13),2,IF(SIGN(G13-H13)=SIGN($E13-$F13),1,0)))) | J13: 1 | K13: 0 | L13: =IF(OR($E13="",$F13=""),"",IF(OR(J13="",K13=""),"",IF(AND(J13=$E13,K13=$F13),2,IF(SIGN(J13-K13)=SIGN($E13-$F13),1,0)))) | M13: 2 | N13: 1 | O13: =IF(OR($E13="",$F13=""),"",IF(OR(M13="",N13=""),"",IF(AND(M13=$E13,N13=$F13),2,IF(SIGN(M13-N13)=SIGN($E13-$F13),1,0)))) | P13: 1 | Q13: 1 | R13: =IF(OR($E13="",$F13=""),"",IF(OR(P13="",Q13=""),"",IF(AND(P13=$E13,Q13=$F13),2,IF(SIGN(P13-Q13)=SIGN($E13-$F13),1,0)))) | S13: 1 | T13: 1 | U13: =IF(OR($E13="",$F13=""),"",IF(OR(S13="",T13=""),"",IF(AND(S13=$E13,T13=$F13),2,IF(SIGN(S13-T13)=SIGN($E13-$F13),1,0)))) | X13: =IF(OR($E13="",$F13=""),"",IF(OR(V13="",W13=""),"",IF(AND(V13=$E13,W13=$F13),2,IF(SIGN(V13-W13)=SIGN($E13-$F13),1,0))))
A14: 12 | B14: F | C14: Suecia | D14: Túnez | E14: 5 | F14: 1 | G14: 1 | H14: 0 | I14: =IF(OR($E14="",$F14=""),"",IF(OR(G14="",H14=""),"",IF(AND(G14=$E14,H14=$F14),2,IF(SIGN(G14-H14)=SIGN($E14-$F14),1,0)))) | J14: 2 | K14: 1 | L14: =IF(OR($E14="",$F14=""),"",IF(OR(J14="",K14=""),"",IF(AND(J14=$E14,K14=$F14),2,IF(SIGN(J14-K14)=SIGN($E14-$F14),1,0)))) | M14: 1 | N14: 0 | O14: =IF(OR($E14="",$F14=""),"",IF(OR(M14="",N14=""),"",IF(AND(M14=$E14,N14=$F14),2,IF(SIGN(M14-N14)=SIGN($E14-$F14),1,0)))) | P14: 2 | Q14: 0 | R14: =IF(OR($E14="",$F14=""),"",IF(OR(P14="",Q14=""),"",IF(AND(P14=$E14,Q14=$F14),2,IF(SIGN(P14-Q14)=SIGN($E14-$F14),1,0)))) | S14: 2 | T14: 1 | U14: =IF(OR($E14="",$F14=""),"",IF(OR(S14="",T14=""),"",IF(AND(S14=$E14,T14=$F14),2,IF(SIGN(S14-T14)=SIGN($E14-$F14),1,0)))) | X14: =IF(OR($E14="",$F14=""),"",IF(OR(V14="",W14=""),"",IF(AND(V14=$E14,W14=$F14),2,IF(SIGN(V14-W14)=SIGN($E14-$F14),1,0))))
... A19: 17 | B19: I | C19: Francia | D19: Senegal | E19: 3 | F19: 1 | G19: 2 | H19: 0 | I19: =IF(OR($E19="",$F19=""),"",IF(OR(G19="",H19=""),"",IF(AND(G19=$E19,H19=$F19),2,IF(SIGN(G19-H19)=SIGN($E19-$F19),1,0)))) | J19: 4 | K19: 1 | L19: =IF(OR($E19="",$F19=""),"",IF(OR(J19="",K19=""),"",IF(AND(J19=$E19,K19=$F19),2,IF(SIGN(J19-K19)=SIGN($E19-$F19),1,0)))) | M19: 2 | N19: 1 | O19: =IF(OR($E19="",$F19=""),"",IF(OR(M19="",N19=""),"",IF(AND(M19=$E19,N19=$F19),2,IF(SIGN(M19-N19)=SIGN($E19-$F19),1,0)))) | P19: 2 | Q19: 1 | R19: =IF(OR($E19="",$F19=""),"",IF(OR(P19="",Q19=""),"",IF(AND(P19=$E19,Q19=$F19),2,IF(SIGN(P19-Q19)=SIGN($E19-$F19),1,0)))) | S19: 2 | T19: 1 | U19: =IF(OR($E19="",$F19=""),"",IF(OR(S19="",T19=""),"",IF(AND(S19=$E19,T19=$F19),2,IF(SIGN(S19-T19)=SIGN($E19-$F19),1,0)))) | X19: =IF(OR($E19="",$F19=""),"",IF(OR(V19="",W19=""),"",IF(AND(V19=$E19,W19=$F19),2,IF(SIGN(V19-W19)=SIGN($E19-$F19),1,0))))
A20: 18 | B20: I | C20: Irak | D20: Noruega | E20: 1 | F20: 4 | G20: 0 | H20: 1 | I20: =IF(OR($E20="",$F20=""),"",IF(OR(G20="",H20=""),"",IF(AND(G20=$E20,H20=$F20),2,IF(SIGN(G20-H20)=SIGN($E20-$F20),1,0)))) | L20: =IF(OR($E20="",$F20=""),"",IF(OR(J20="",K20=""),"",IF(AND(J20=$E20,K20=$F20),2,IF(SIGN(J20-K20)=SIGN($E20-$F20),1,0)))) | M20: 0 | N20: 2 | O20: =IF(OR($E20="",$F20=""),"",IF(OR(M20="",N20=""),"",IF(AND(M20=$E20,N20=$F20),2,IF(SIGN(M20-N20)=SIGN($E20-$F20),1,0)))) | P20: 0 | Q20: 2 | R20: =IF(OR($E20="",$F20=""),"",IF(OR(P20="",Q20=""),"",IF(AND(P20=$E20,Q20=$F20),2,IF(SIGN(P20-Q20)=SIGN($E20-$F20),1,0)))) | U20: =IF(OR($E20="",$F20=""),"",IF(OR(S20="",T20=""),"",IF(AND(S20=$E20,T20=$F20),2,IF(SIGN(S20-T20)=SIGN($E20-$F20),1,0)))) | X20: =IF(OR($E20="",$F20=""),"",IF(OR(V20="",W20=""),"",IF(AND(V20=$E20,W20=$F20),2,IF(SIGN(V20-W20)=SIGN($E20-$F20),1,0))))
A21: 19 | B21: J | C21: Argentina | D21: Argelia | E21: 3 | F21: 0 | G21: 2 | H21: 0 | I21: =IF(OR($E21="",$F21=""),"",IF(OR(G21="",H21=""),"",IF(AND(G21=$E21,H21=$F21),2,IF(SIGN(G21-H21)=SIGN($E21-$F21),1,0)))) | J21: 4 | K21: 0 | L21: =IF(OR($E21="",$F21=""),"",IF(OR(J21="",K21=""),"",IF(AND(J21=$E21,K21=$F21),2,IF(SIGN(J21-K21)=SIGN($E21-$F21),1,0)))) | M21: 2 | N21: 0 | O21: =IF(OR($E21="",$F21=""),"",IF(OR(M21="",N21=""),"",IF(AND(M21=$E21,N21=$F21),2,IF(SIGN(M21-N21)=SIGN($E21-$F21),1,0)))) | P21: 3 | Q21: 1 | R21: =IF(OR($E21="",$F21=""),"",IF(OR(P21="",Q21=""),"",IF(AND(P21=$E21,Q21=$F21),2,IF(SIGN(P21-Q21)=SIGN($E21-$F21),1,0)))) | S21: 2 | T21: 1 | U21: =IF(OR($E21="",$F21=""),"",IF(OR(S21="",T21=""),"",IF(AND(S21=$E21,T21=$F21),2,IF(SIGN(S21-T21)=SIGN($E21-$F21),1,0)))) | X21: =IF(OR($E21="",$F21=""),"",IF(OR(V21="",W21=""),"",IF(AND(V21=$E21,W21=$F21),2,IF(SIGN(V21-W21)=SIGN($E21-$F21),1,0))))
A22: 20 | B22: J | C22: Austria | D22: Jordania | E22: 3 | F22: 1 | G22: 1 | H22: 0 | I22: =IF(OR($E22="",$F22=""),"",IF(OR(G22="",H22=""),"",IF(AND(G22=$E22,H22=$F22),2,IF(SIGN(G22-H22)=SIGN($E22-$F22),1,0)))) | L22: =IF(OR($E22="",$F22=""),"",IF(OR(J22="",K22=""),"",IF(AND(J22=$E22,K22=$F22),2,IF(SIGN(J22-K22)=SIGN($E22-$F22),1,0)))) | M22: 2 | N22: 0 | O22: =IF(OR($E22="",$F22=""),"",IF(OR(M22="",N22=""),"",IF(AND(M22=$E22,N22=$F22),2,IF(SIGN(M22-N22)=SIGN($E22-$F22),1,0)))) | P22: 3 | Q22: 0 | R22: =IF(OR($E22="",$F22=""),"",IF(OR(P22="",Q22=""),"",IF(AND(P22=$E22,Q22=$F22),2,IF(SIGN(P22-Q22)=SIGN($E22-$F22),1,0)))) | U22: =IF(OR($E22="",$F22=""),"",IF(OR(S22="",T22=""),"",IF(AND(S22=$E22,T22=$F22),2,IF(SIGN(S22-T22)=SIGN($E22-$F22),1,0)))) | X22: =IF(OR($E22="",$F22=""),"",IF(OR(V22="",W22=""),"",IF(AND(V22=$E22,W22=$F22),2,IF(SIGN(V22-W22)=SIGN($E22-$F22),1,0))))
A23: 21 | B23: K | C23: Portugal | D23: RD Congo | E23: 1 | F23: 1 | G23: 1 | H23: 0 | I23: =IF(OR($E23="",$F23=""),"",IF(OR(G23="",H23=""),"",IF(AND(G23=$E23,H23=$F23),2,IF(SIGN(G23-H23)=SIGN($E23-$F23),1,0)))) | J23: 1 | K23: 1 | L23: =IF(OR($E23="",$F23=""),"",IF(OR(J23="",K23=""),"",IF(AND(J23=$E23,K23=$F23),2,IF(SIGN(J23-K23)=SIGN($E23-$F23),1,0)))) | M23: 2 | N23: 1 | O23: =IF(OR($E23="",$F23=""),"",IF(OR(M23="",N23=""),"",IF(AND(M23=$E23,N23=$F23),2,IF(SIGN(M23-N23)=SIGN($E23-$F23),1,0)))) | P23: 2 | Q23: 1 | R23: =IF(OR($E23="",$F23=""),"",IF(OR(P23="",Q23=""),"",IF(AND(P23=$E23,Q23=$F23),2,IF(SIGN(P23-Q23)=SIGN($E23-$F23),1,0)))) | U23: =IF(OR($E23="",$F23=""),"",IF(OR(S23="",T23=""),"",IF(AND(S23=$E23,T23=$F23),2,IF(SIGN(S23-T23)=SIGN($E23-$F23),1,0)))) | X23: =IF(OR($E23="",$F23=""),"",IF(OR(V23="",W23=""),"",IF(AND(V23=$E23,W23=$F23),2,IF(SIGN(V23-W23)=SIGN($E23-$F23),1,0))))
A24: 22 | B24: K | C24: Uzbekistán | D24: Colombia | E24: 1 | F24: 3 | G24: 0 | H24: 2 | I24: =IF(OR($E24="",$F24=""),"",IF(OR(G24="",H24=""),"",IF(AND(G24=$E24,H24=$F24),2,IF(SIGN(G24-H24)=SIGN($E24-$F24),1,0)))) | J24: 0 | K24: 4 | L24: =IF(OR($E24="",$F24=""),"",IF(OR(J24="",K24=""),"",IF(AND(J24=$E24,K24=$F24),2,IF(SIGN(J24-K24)=SIGN($E24-$F24),1,0)))) | M24: 0 | N24: 1 | O24: =IF(OR($E24="",$F24=""),"",IF(OR(M24="",N24=""),"",IF(AND(M24=$E24,N24=$F24),2,IF(SIGN(M24-N24)=SIGN($E24-$F24),1,0)))) | P24: 0 | Q24: 4 | R24: =IF(OR($E24="",$F24=""),"",IF(OR(P24="",Q24=""),"",IF(AND(P24=$E24,Q24=$F24),2,IF(SIGN(P24-Q24)=SIGN($E24-$F24),1,0)))) | U24: =IF(OR($E24="",$F24=""),"",IF(OR(S24="",T24=""),"",IF(AND(S24=$E24,T24=$F24),2,IF(SIGN(S24-T24)=SIGN($E24-$F24),1,0)))) | X24: =IF(OR($E24="",$F24=""),"",IF(OR(V24="",W24=""),"",IF(AND(V24=$E24,W24=$F24),2,IF(SIGN(V24-W24)=SIGN($E24-$F24),1,0))))
A25: 23 | B25: L | C25: Inglaterra | D25: Croacia | E25: 4 | F25: 2 | G25: 1 | H25: 1 | I25: =IF(OR($E25="",$F25=""),"",IF(OR(G25="",H25=""),"",IF(AND(G25=$E25,H25=$F25),2,IF(SIGN(G25-H25)=SIGN($E25-$F25),1,0)))) | J25: 2 | K25: 2 | L25: =IF(OR($E25="",$F25=""),"",IF(OR(J25="",K25=""),"",IF(AND(J25=$E25,K25=$F25),2,IF(SIGN(J25-K25)=SIGN($E25-$F25),1,0)))) | M25: 1 | N25: 1 | O25: =IF(OR($E25="",$F25=""),"",IF(OR(M25="",N25=""),"",IF(AND(M25=$E25,N25=$F25),2,IF(SIGN(M25-N25)=SIGN($E25-$F25),1,0)))) | P25: 2 | Q25: 2 | R25: =IF(OR($E25="",$F25=""),"",IF(OR(P25="",Q25=""),"",IF(AND(P25=$E25,Q25=$F25),2,IF(SIGN(P25-Q25)=SIGN($E25-$F25),1,0)))) | U25: =IF(OR($E25="",$F25=""),"",IF(OR(S25="",T25=""),"",IF(AND(S25=$E25,T25=$F25),2,IF(SIGN(S25-T25)=SIGN($E25-$F25),1,0)))) | X25: =IF(OR($E25="",$F25=""),"",IF(OR(V25="",W25=""),"",IF(AND(V25=$E25,W25=$F25),2,IF(SIGN(V25-W25)=SIGN($E25-$F25),1,0))))
A26: 24 | B26: L | C26: Ghana | D26: Panamá | E26: 1 | F26: 0 | G26: 1 | H26: 0 | I26: =IF(OR($E26="",$F26=""),"",IF(OR(G26="",H26=""),"",IF(AND(G26=$E26,H26=$F26),2,IF(SIGN(G26-H26)=SIGN($E26-$F26),1,0)))) | J26: 2 | K26: 1 | L26: =IF(OR($E26="",$F26=""),"",IF(OR(J26="",K26=""),"",IF(AND(J26=$E26,K26=$F26),2,IF(SIGN(J26-K26)=SIGN($E26-$F26),1,0)))) | M26: 1 | N26: 1 | O26: =IF(OR($E26="",$F26=""),"",IF(OR(M26="",N26=""),"",IF(AND(M26=$E26,N26=$F26),2,IF(SIGN(M26-N26)=SIGN($E26-$F26),1,0)))) | P26: 3 | Q26: 0 | R26: =IF(OR($E26="",$F26=""),"",IF(OR(P26="",Q26=""),"",IF(AND(P26=$E26,Q26=$F26),2,IF(SIGN(P26-Q26)=SIGN($E26-$F26),1,0)))) | U26: =IF(OR($E26="",$F26=""),"",IF(OR(S26="",T26=""),"",IF(AND(S26=$E26,T26=$F26),2,IF(SIGN(S26-T26)=SIGN($E26-$F26),1,0)))) | X26: =IF(OR($E26="",$F26=""),"",IF(OR(V26="",W26=""),"",IF(AND(V26=$E26,W26=$F26),2,IF(SIGN(V26-W26)=SIGN($E26-$F26),1,0))))
D27: PUNTOS JORNADA | I27: =SUM(I3:I26) | L27: =SUM(L3:L26) | O27: =SUM(O3:O26) | R27: =SUM(R3:R26) | U27: =SUM(U3:U26) | X27: =SUM(X3:X26)

Sheet Jornada 2
A1: PARTIDO | E1: RESULTADO REAL | G1: Jugador 1 | J1: Jugador 2 | M1: Jugador 3 | P1: Jugador 4 | S1: Jugador 5 | V1: Jugador 6
A2: Nº | B2: Grupo | C2: LOCAL | D2: VISITANTE | E2: GL | F2: GV | G2: GL | H2: GV | I2: Pts | J2: GL | K2: GV | L2: Pts | M2: GL | N2: GV | O2: Pts | P2: GL | Q2: GV | R2: Pts | S2: GL | T2: GV | U2: Pts | V2: GL | W2: GV | X2: Pts
A3: 25 | B3: A | C3: México | D3: Corea del Sur | E3: 1 | F3: 0 | G3: 2 | H3: 1 | I3: =IF(OR($E3="",$F3=""),"",IF(OR(G3="",H3=""),"",IF(AND(G3=$E3,H3=$F3),2,IF(SIGN(G3-H3)=SIGN($E3-$F3),1,0)))) | L3: =IF(OR($E3="",$F3=""),"",IF(OR(J3="",K3=""),"",IF(AND(J3=$E3,K3=$F3),2,IF(SIGN(J3-K3)=SIGN($E3-$F3),1,0)))) | M3: 2 | N3: 1 | O3: =IF(OR($E3="",$F3=""),"",IF(OR(M3="",N3=""),"",IF(AND(M3=$E3,N3=$F3),2,IF(SIGN(M3-N3)=SIGN($E3-$F3),1,0)))) | P3: 0 | Q3: 1 | R3: =IF(OR($E3="",$F3=""),"",IF(OR(P3="",Q3=""),"",IF(AND(P3=$E3,Q3=$F3),2,IF(SIGN(P3-Q3)=SIGN($E3-$F3),1,0)))) | S3: 2 | T3: 2 | U3: =IF(OR($E3="",$F3=""),"",IF(OR(S3="",T3=""),"",IF(AND(S3=$E3,T3=$F3),2,IF(SIGN(S3-T3)=SIGN($E3-$F3),1,0)))) | X3: =IF(OR($E3="",$F3=""),"",IF(OR(V3="",W3=""),"",IF(AND(V3=$E3,W3=$F3),2,IF(SIGN(V3-W3)=SIGN($E3-$F3),1,0))))
A4: 26 | B4: A | C4: República Checa | D4: Sudáfrica | E4: 1 | F4: 1 | G4: 1 | H4: 1 | I4: =IF(OR($E4="",$F4=""),"",IF(OR(G4="",H4=""),"",IF(AND(G4=$E4,H4=$F4),2,IF(SIGN(G4-H4)=SIGN($E4-$F4),1,0)))) | L4: =IF(OR($E4="",$F4=""),"",IF(OR(J4="",K4=""),"",IF(AND(J4=$E4,K4=$F4),2,IF(SIGN(J4-K4)=SIGN($E4-$F4),1,0)))) | M4: 1 | N4: 1 | O4: =IF(OR($E4="",$F4=""),"",IF(OR(M4="",N4=""),"",IF(AND(M4=$E4,N4=$F4),2,IF(SIGN(M4-N4)=SIGN($E4-$F4),1,0)))) | P4: 1 | Q4: 0 | R4: =IF(OR($E4="",$F4=""),"",IF(OR(P4="",Q4=""),"",IF(AND(P4=$E4,Q4=$F4),2,IF(SIGN(P4-Q4)=SIGN($E4-$F4),1,0)))) | S4: 2 | T4: 1 | U4: =IF(OR($E4="",$F4=""),"",IF(OR(S4="",T4=""),"",IF(AND(S4=$E4,T4=$F4),2,IF(SIGN(S4-T4)=SIGN($E4-$F4),1,0)))) | X4: =IF(OR($E4="",$F4=""),"",IF(OR(V4="",W4=""),"",IF(AND(V4=$E4,W4=$F4),2,IF(SIGN(V4-W4)=SIGN($E4-$F4),1,0))))
A5: 27 | B5: B | C5: Canadá | D5: Catar | E5: 6 | F5: 0 | G5: 3 | H5: 0 | I5: =IF(OR($E5="",$F5=""),"",IF(OR(G5="",H5=""),"",IF(AND(G5=$E5,H5=$F5),2,IF(SIGN(G5-H5)=SIGN($E5-$F5),1,0)))) | L5: =IF(OR($E5="",$F5=""),"",IF(OR(J5="",K5=""),"",IF(AND(J5=$E5,K5=$F5),2,IF(SIGN(J5-K5)=SIGN($E5-$F5),1,0)))) | M5: 2 | N5: 0 | O5: =IF(OR($E5="",$F5=""),"",IF(OR(M5="",N5=""),"",IF(AND(M5=$E5,N5=$F5),2,IF(SIGN(M5-N5)=SIGN($E5-$F5),1,0)))) | P5: 0 | Q5: 1 | R5: =IF(OR($E5="",$F5=""),"",IF(OR(P5="",Q5=""),"",IF(AND(P5=$E5,Q5=$F5),2,IF(SIGN(P5-Q5)=SIGN($E5-$F5),1,0)))) | S5: 2 | T5: 0 | U5: =IF(OR($E5="",$F5=""),"",IF(OR(S5="",T5=""),"",IF(AND(S5=$E5,T5=$F5),2,IF(SIGN(S5-T5)=SIGN($E5-$F5),1,0)))) | X5: =IF(OR($E5="",$F5=""),"",IF(OR(V5="",W5=""),"",IF(AND(V5=$E5,W5=$F5),2,IF(SIGN(V5-W5)=SIGN($E5-$F5),1,0))))
A6: 28 | B6: B | C6: Suiza | D6: Bosnia y Herzegovina | E6: 4 | F6: 1 | G6: 2 | H6: 1 | I6: =IF(OR($E6="",$F6=""),"",IF(OR(G6="",H6=""),"",IF(AND(G6=$E6,H6=$F6),2,IF(SIGN(G6-H6)=SIGN($E6-$F6),1,0)))) | J6: 1 | K6: 0 | L6: =IF(OR($E6="",$F6=""),"",IF(OR(J6="",K6=""),"",IF(AND(J6=$E6,K6=$F6),2,IF(SIGN(J6-K6)=SIGN($E6-$F6),1,0)))) | M6: 2 | N6: 1 | O6: =IF(OR($E6="",$F6=""),"",IF(OR(M6="",N6=""),"",IF(AND(M6=$E6,N6=$F6),2,IF(SIGN(M6-N6)=SIGN($E6-$F6),1,0)))) | P6: 1 | Q6: 1 | R6: =IF(OR($E6="",$F6=""),"",IF(OR(P6="",Q6=""),"",IF(AND(P6=$E6,Q6=$F6),2,IF(SIGN(P6-Q6)=SIGN($E6-$F6),1,0)))) | S6: 2 | T6: 1 | U6: =IF(OR($E6="",$F6=""),"",IF(OR(S6="",T6=""),"",IF(AND(S6=$E6,T6=$F6),2,IF(SIGN(S6-T6)=SIGN($E6-$F6),1,0)))) | X6: =IF(OR($E6="",$F6=""),"",IF(OR(V6="",W6=""),"",IF(AND(V6=$E6,W6=$F6),2,IF(SIGN(V6-W6)=SIGN($E6-$F6),1,0))))
A7: 29 | B7: C | C7: Brasil | D7: Haití | E7: 3 | F7: 0 | G7: 4 | H7: 0 | I7: =IF(OR($E7="",$F7=""),"",IF(OR(G7="",H7=""),"",IF(AND(G7=$E7,H7=$F7),2,IF(SIGN(G7-H7)=SIGN($E7-$F7),1,0)))) | J7: 5 | K7: 1 | L7: =IF(OR($E7="",$F7=""),"",IF(OR(J7="",K7=""),"",IF(AND(J7=$E7,K7=$F7),2,IF(SIGN(J7-K7)=SIGN($E7-$F7),1,0)))) | M7: 4 | N7: 0 | O7: =IF(OR($E7="",$F7=""),"",IF(OR(M7="",N7=""),"",IF(AND(M7=$E7,N7=$F7),2,IF(SIGN(M7-N7)=SIGN($E7-$F7),1,0)))) | P7: 5 | Q7: 0 | R7: =IF(OR($E7="",$F7=""),"",IF(OR(P7="",Q7=""),"",IF(AND(P7=$E7,Q7=$F7),2,IF(SIGN(P7-Q7)=SIGN($E7-$F7),1,0)))) | S7: 4 | T7: 0 | U7: =IF(OR($E7="",$F7=""),"",IF(OR(S7="",T7=""),"",IF(AND(S7=$E7,T7=$F7),2,IF(SIGN(S7-T7)=SIGN($E7-$F7),1,0)))) | X7: =IF(OR($E7="",$F7=""),"",IF(OR(V7="",W7=""),"",IF(AND(V7=$E7,W7=$F7),2,IF(SIGN(V7-W7)=SIGN($E7-$F7),1,0))))
A8: 30 | B8: C | C8: Escocia | D8: Marruecos | E8: 0 | F8: 1 | G8: 0 | H8: 3 | I8: =IF(OR($E8="",$F8=""),"",IF(OR(G8="",H8=""),"",IF(AND(G8=$E8,H8=$F8),2,IF(SIGN(G8-H8)=SIGN($E8-$F8),1,0)))) | J8: 2 | K8: 1 | L8: =IF(OR($E8="",$F8=""),"",IF(OR(J8="",K8=""),"",IF(AND(J8=$E8,K8=$F8),2,IF(SIGN(J8-K8)=SIGN($E8-$F8),1,0)))) | M8: 1 | N8: 2 | O8: =IF(OR($E8="",$F8=""),"",IF(OR(M8="",N8=""),"",IF(AND(M8=$E8,N8=$F8),2,IF(SIGN(M8-N8)=SIGN($E8-$F8),1,0)))) | P8: 1 | Q8: 2 | R8: =IF(OR($E8="",$F8=""),"",IF(OR(P8="",Q8=""),"",IF(AND(P8=$E8,Q8=$F8),2,IF(SIGN(P8-Q8)=SIGN($E8-$F8),1,0)))) | S8: 1 | T8: 2 | U8: =IF(OR($E8="",$F8=""),"",IF(OR(S8="",T8=""),"",IF(AND(S8=$E8,T8=$F8),2,IF(SIGN(S8-T8)=SIGN($E8-$F8),1,0)))) | X8: =IF(OR($E8="",$F8=""),"",IF(OR(V8="",W8=""),"",IF(AND(V8=$E8,W8=$F8),2,IF(SIGN(V8-W8)=SIGN($E8-$F8),1,0))))
A9: 31 | B9: D | C9: Estados Unidos | D9: Australia | E9: 2 | F9: 0 | G9: 2 | H9: 0 | I9: =IF(OR($E9="",$F9=""),"",IF(OR(G9="",H9=""),"",IF(AND(G9=$E9,H9=$F9),2,IF(SIGN(G9-H9)=SIGN($E9-$F9),1,0)))) | J9: 1 | K9: 1 | L9: =IF(OR($E9="",$F9=""),"",IF(OR(J9="",K9=""),"",IF(AND(J9=$E9,K9=$F9),2,IF(SIGN(J9-K9)=SIGN($E9-$F9),1,0)))) | M9: 2 | N9: 0 | O9: =IF(OR($E9="",$F9=""),"",IF(OR(M9="",N9=""),"",IF(AND(M9=$E9,N9=$F9),2,IF(SIGN(M9-N9)=SIGN($E9-$F9),1,0)))) | P9: 2 | Q9: 0 | R9: =IF(OR($E9="",$F9=""),"",IF(OR(P9="",Q9=""),"",IF(AND(P9=$E9,Q9=$F9),2,IF(SIGN(P9-Q9)=SIGN($E9-$F9),1,0)))) | S9: 3 | T9: 1 | U9: =IF(OR($E9="",$F9=""),"",IF(OR(S9="",T9=""),"",IF(AND(S9=$E9,T9=$F9),2,IF(SIGN(S9-T9)=SIGN($E9-$F9),1,0)))) | X9: =IF(OR($E9="",$F9=""),"",IF(OR(V9="",W9=""),"",IF(AND(V9=$E9,W9=$F9),2,IF(SIGN(V9-W9)=SIGN($E9-$F9),1,0))))
A10: 32 | B10: D | C10: Turquía | D10: Paraguay | E10: 0 | F10: 1 | G10: 2 | H10: 1 | I10: =IF(OR($E10="",$F10=""),"",IF(OR(G10="",H10=""),"",IF(AND(G10=$E10,H10=$F10),2,IF(SIGN(G10-H10)=SIGN($E10-$F10),1,0)))) | J10: 2 | K10: 1 | L10: =IF(OR($E10="",$F10=""),"",IF(OR(J10="",K10=""),"",IF(AND(J10=$E10,K10=$F10),2,IF(SIGN(J10-K10)=SIGN($E10-$F10),1,0)))) | M10: 2 | N10: 1 | O10: =IF(OR($E10="",$F10=""),"",IF(OR(M10="",N10=""),"",IF(AND(M10=$E10,N10=$F10),2,IF(SIGN(M10-N10)=SIGN($E10-$F10),1,0)))) | P10: 1 | Q10: 1 | R10: =IF(OR($E10="",$F10=""),"",IF(OR(P10="",Q10=""),"",IF(AND(P10=$E10,Q10=$F10),2,IF(SIGN(P10-Q10)=SIGN($E10-$F10),1,0)))) | S10: 2 | T10: 1 | U10: =IF(OR($E10="",$F10=""),"",IF(OR(S10="",T10=""),"",IF(AND(S10=$E10,T10=$F10),2,IF(SIGN(S10-T10)=SIGN($E10-$F10),1,0)))) | X10: =IF(OR($E10="",$F10=""),"",IF(OR(V10="",W10=""),"",IF(AND(V10=$E10,W10=$F10),2,IF(SIGN(V10-W10)=SIGN($E10-$F10),1,0))))
A11: 33 | B11: E | C11: Alemania | D11: Costa de Marfil | E11: 2 | F11: 1 | G11: 3 | H11: 1 | I11: =IF(OR($E11="",$F11=""),"",IF(OR(G11="",H11=""),"",IF(AND(G11=$E11,H11=$F11),2,IF(SIGN(G11-H11)=SIGN($E11-$F11),1,0)))) | J11: 2 | K11: 0 | L11: =IF(OR($E11="",$F11=""),"",IF(OR(J11="",K11=""),"",IF(AND(J11=$E11,K11=$F11),2,IF(SIGN(J11-K11)=SIGN($E11-$F11),1,0)))) | M11: 3 | N11: 1 | O11: =IF(OR($E11="",$F11=""),"",IF(OR(M11="",N11=""),"",IF(AND(M11=$E11,N11=$F11),2,IF(SIGN(M11-N11)=SIGN($E11-$F11),1,0)))) | P11: 2 | Q11: 0 | R11: =IF(OR($E11="",$F11=""),"",IF(OR(P11="",Q11=""),"",IF(AND(P11=$E11,Q11=$F11),2,IF(SIGN(P11-Q11)=SIGN($E11-$F11),1,0)))) | S11: 2 | T11: 1 | U11: =IF(OR($E11="",$F11=""),"",IF(OR(S11="",T11=""),"",IF(AND(S11=$E11,T11=$F11),2,IF(SIGN(S11-T11)=SIGN($E11-$F11),1,0)))) | X11: =IF(OR($E11="",$F11=""),"",IF(OR(V11="",W11=""),"",IF(AND(V11=$E11,W11=$F11),2,IF(SIGN(V11-W11)=SIGN($E11-$F11),1,0))))
A12: 34 | B12: E | C12: Ecuador | D12: Curazao | E12: 0 | F12: 0 | G12: 2 | H12: 0 | I12: =IF(OR($E12="",$F12=""),"",IF(OR(G12="",H12=""),"",IF(AND(G12=$E12,H12=$F12),2,IF(SIGN(G12-H12)=SIGN($E12-$F12),1,0)))) | J12: 1 | K12: 0 | L12: =IF(OR($E12="",$F12=""),"",IF(OR(J12="",K12=""),"",IF(AND(J12=$E12,K12=$F12),2,IF(SIGN(J12-K12)=SIGN($E12-$F12),1,0)))) | M12: 2 | N12: 0 | O12: =IF(OR($E12="",$F12=""),"",IF(OR(M12="",N12=""),"",IF(AND(M12=$E12,N12=$F12),2,IF(SIGN(M12-N12)=SIGN($E12-$F12),1,0)))) | P12: 3 | Q12: 0 | R12: =IF(OR($E12="",$F12=""),"",IF(OR(P12="",Q12=""),"",IF(AND(P12=$E12,Q12=$F12),2,IF(SIGN(P12-Q12)=SIGN($E12-$F12),1,0)))) | S12: 3 | T12: 0 | U12: =IF(OR($E12="",$F12=""),"",IF(OR(S12="",T12=""),"",IF(AND(S12=$E12,T12=$F12),2,IF(SIGN(S12-T12)=SIGN($E12-$F12),1,0)))) | X12: =IF(OR($E12="",$F12=""),"",IF(OR(V12="",W12=""),"",IF(AND(V12=$E12,W12=$F12),2,IF(SIGN(V12-W12)=SIGN($E12-$F12),1,0))))
A13: 35 | B13: F | C13: Países Bajos | D13: Suecia | E13: 5 | F13: 1 | G13: 3 | H13: 1 | I13: =IF(OR($E13="",$F13=""),"",IF(OR(G13="",H13=""),"",IF(AND(G13=$E13,H13=$F13),2,IF(SIGN(G13-H13)=SIGN($E13-$F13),1,0)))) | J13: 2 | K13: 1 | L13: =IF(OR($E13="",$F13=""),"",IF(OR(J13="",K13=""),"",IF(AND(J13=$E13,K13=$F13),2,IF(SIGN(J13-K13)=SIGN($E13-$F13),1,0)))) | M13: 2 | N13: 1 | O13: =IF(OR($E13="",$F13=""),"",IF(OR(M13="",N13=""),"",IF(AND(M13=$E13,N13=$F13),2,IF(SIGN(M13-N13)=SIGN($E13-$F13),1,0)))) | P13: 1 | Q13: 2 | R13: =IF(OR($E13="",$F13=""),"",IF(OR(P13="",Q13=""),"",IF(AND(P13=$E13,Q13=$F13),2,IF(SIGN(P13-Q13)=SIGN($E13-$F13),1,0)))) | S13: 2 | T13: 1 | U13: =IF(OR($E13="",$F13=""),"",IF(OR(S13="",T13=""),"",IF(AND(S13=$E13,T13=$F13),2,IF(SIGN(S13-T13)=SIGN($E13-$F13),1,0)))) | X13: =IF(OR($E13="",$F13=""),"",IF(OR(V13="",W13=""),"",IF(AND(V13=$E13,W13=$F13),2,IF(SIGN(V13-W13)=SIGN($E13-$F13),1,0))))
A14: 36 | B14: F | C14: Túnez | D14: Japón | E14: 0 | F14: 4 | G14: 1 | H14: 3 | I14: =IF(OR($E14="",$F14=""),"",IF(OR(G14="",H14=""),"",IF(AND(G14=$E14,H14=$F14),2,IF(SIGN(G14-H14)=SIGN($E14-$F14),1,0)))) | J14: 1 | K14: 2 | L14: =IF(OR($E14="",$F14=""),"",IF(OR(J14="",K14=""),"",IF(AND(J14=$E14,K14=$F14),2,IF(SIGN(J14-K14)=SIGN($E14-$F14),1,0)))) | M14: 1 | N14: 1 | O14: =IF(OR($E14="",$F14=""),"",IF(OR(M14="",N14=""),"",IF(AND(M14=$E14,N14=$F14),2,IF(SIGN(M14-N14)=SIGN($E14-$F14),1,0)))) | P14: 1 | Q14: 2 | R14: =IF(OR($E14="",$F14=""),"",IF(OR(P14="",Q14=""),"",IF(AND(P14=$E14,Q14=$F14),2,IF(SIGN(P14-Q14)=SIGN($E14-$F14),1,0)))) | S14: 1 | T14: 2 | U14: =IF(OR($E14="",$F14=""),"",IF(OR(S14="",T14=""),"",IF(AND(S14=$E14,T14=$F14),2,IF(SIGN(S14-T14)=SIGN($E14-$F14),1,0)))) | X14: =IF(OR($E14="",$F14=""),"",IF(OR(V14="",W14=""),"",IF(AND(V14=$E14,W14=$F14),2,IF(SIGN(V14-W14)=SIGN($E14-$F14),1,0))))
A15: 37 | B15: G | C15: Bélgica | D15: Irán | E15: 0 | F15: 0 | G15: 2 | H15: 0 | I15: =IF(OR($E15="",$F15=""),"",IF(OR(G15="",H15=""),"",IF(AND(G15=$E15,H15=$F15),2,IF(SIGN(G15-H15)=SIGN($E15-$F15),1,0)))) | J15: 2 | K15: 0 | L15: =IF(OR($E15="",$F15=""),"",IF(OR(J15="",K15=""),"",IF(AND(J15=$E15,K15=$F15),2,IF(SIGN(J15-K15)=SIGN($E15-$F15),1,0)))) | M15: 2 | N15: 0 | O15: =IF(OR($E15="",$F15=""),"",IF(OR(M15="",N15=""),"",IF(AND(M15=$E15,N15=$F15),2,IF(SIGN(M15-N15)=SIGN($E15-$F15),1,0)))) | P15: 3 | Q15: 1 | R15: =IF(OR($E15="",$F15=""),"",IF(OR(P15="",Q15=""),"",IF(AND(P15=$E15,Q15=$F15),2,IF(SIGN(P15-Q15)=SIGN($E15-$F15),1,0)))) | S15: 2 | T15: 2 | U15: =IF(OR($E15="",$F15=""),"",IF(OR(S15="",T15=""),"",IF(AND(S15=$E15,T15=$F15),2,IF(SIGN(S15-T15)=SIGN($E15-$F15),1,0)))) | X15: =IF(OR($E15="",$F15=""),"",IF(OR(V15="",W15=""),"",IF(AND(V15=$E15,W15=$F15),2,IF(SIGN(V15-W15)=SIGN($E15-$F15),1,0))))
A16: 38 | B16: G | C16: Nueva Zelanda | D16: Egipto | E16: 1 | F16: 3 | G16: 0 | H16: 2 | I16: =IF(OR($E16="",$F16=""),"",IF(OR(G16="",H16=""),"",IF(AND(G16=$E16,H16=$F16),2,IF(SIGN(G16-H16)=SIGN($E16-$F16),1,0)))) | J16: 1 | K16: 0 | L16: =IF(OR($E16="",$F16=""),"",IF(OR(J16="",K16=""),"",IF(AND(J16=$E16,K16=$F16),2,IF(SIGN(J16-K16)=SIGN($E16-$F16),1,0)))) | M16: 0 | N16: 2 | O16: =IF(OR($E16="",$F16=""),"",IF(OR(M16="",N16=""),"",IF(AND(M16=$E16,N16=$F16),2,IF(SIGN(M16-N16)=SIGN($E16-$F16),1,0)))) | P16: 0 | Q16: 3 | R16: =IF(OR($E16="",$F16=""),"",IF(OR(P16="",Q16=""),"",IF(AND(P16=$E16,Q16=$F16),2,IF(SIGN(P16-Q16)=SIGN($E16-$F16),1,0)))) | S16: 1 | T16: 2 | U16: =IF(OR($E16="",$F16=""),"",IF(OR(S16="",T16=""),"",IF(AND(S16=$E16,T16=$F16),2,IF(SIGN(S16-T16)=SIGN($E16-$F16),1,0)))) | X16: =IF(OR($E16="",$F16=""),"",IF(OR(V16="",W16=""),"",IF(AND(V16=$E16,W16=$F16),2,IF(SIGN(V16-W16)=SIGN($E16-$F16),1,0))))
A17: 39 | B17: H | C17: España | D17: Arabia Saudita | E17: 4 | F17: 0 | G17: 4 | H17: 0 | I17: =IF(OR($E17="",$F17=""),"",IF(OR(G17="",H17=""),"",IF(AND(G17=$E17,H17=$F17),2,IF(SIGN(G17-H17)=SIGN($E17-$F17),1,0)))) | J17: 1 | K17: 0 | L17: =IF(OR($E17="",$F17=""),"",IF(OR(J17="",K17=""),"",IF(AND(J17=$E17,K17=$F17),2,IF(SIGN(J17-K17)=SIGN($E17-$F17),1,0)))) | M17: 4 | N17: 0 | O17: =IF(OR($E17="",$F17=""),"",IF(OR(M17="",N17=""),"",IF(AND(M17=$E17,N17=$F17),2,IF(SIGN(M17-N17)=SIGN($E17-$F17),1,0)))) | P17: 4 | Q17: 1 | R17: =IF(OR($E17="",$F17=""),"",IF(OR(P17="",Q17=""),"",IF(AND(P17=$E17,Q17=$F17),2,IF(SIGN(P17-Q17)=SIGN($E17-$F17),1,0)))) | S17: 3 | T17: 0 | U17: =IF(OR($E17="",$F17=""),"",IF(OR(S17="",T17=""),"",IF(AND(S17=$E17,T17=$F17),2,IF(SIGN(S17-T17)=SIGN($E17-$F17),1,0)))) | X17: =IF(OR($E17="",$F17=""),"",IF(OR(V17="",W17=""),"",IF(AND(V17=$E17,W17=$F17),2,IF(SIGN(V17-W17)=SIGN($E17-$F17),1,0))))
... A26: 48 | B26: L | C26: Panamá | D26: Croacia | E26: 0 | F26: 1 | G26: 1 | H26: 3 | I26: =IF(OR($E26="",$F26=""),"",IF(OR(G26="",H26=""),"",IF(AND(G26=$E26,H26=$F26),2,IF(SIGN(G26-H26)=SIGN($E26-$F26),1,0)))) | J26: 0 | K26: 2 | L26: =IF(OR($E26="",$F26=""),"",IF(OR(J26="",K26=""),"",IF(AND(J26=$E26,K26=$F26),2,IF(SIGN(J26-K26)=SIGN($E26-$F26),1,0)))) | M26: 1 | N26: 2 | O26: =IF(OR($E26="",$F26=""),"",IF(OR(M26="",N26=""),"",IF(AND(M26=$E26,N26=$F26),2,IF(SIGN(M26-N26)=SIGN($E26-$F26),1,0)))) | P26: 0 | Q26: 4 | R26: =IF(OR($E26="",$F26=""),"",IF(OR(P26="",Q26=""),"",IF(AND(P26=$E26,Q26=$F26),2,IF(SIGN(P26-Q26)=SIGN($E26-$F26),1,0)))) | S26: 1 | T26: 2 | U26: =IF(OR($E26="",$F26=""),"",IF(OR(S26="",T26=""),"",IF(AND(S26=$E26,T26=$F26),2,IF(SIGN(S26-T26)=SIGN($E26-$F26),1,0)))) | X26: =IF(OR($E26="",$F26=""),"",IF(OR(V26="",W26=""),"",IF(AND(V26=$E26,W26=$F26),2,IF(SIGN(V26-W26)=SIGN($E26-$F26),1,0))))
D27: PUNTOS JORNADA | I27: =SUM(I3:I26) | L27: =SUM(L3:L26) | O27: =SUM(O3:O26) | R27: =SUM(R3:R26) | U27: =SUM(U3:U26) | X27: =SUM(X3:X26)

Sheet Jornada 3
A1: PARTIDO | E1: RESULTADO REAL | G1: Jugador 1 | J1: Jugador 2 | M1: Jugador 3 | P1: Jugador 4 | S1: Jugador 5 | V1: Jugador 6
A2: Nº | B2: Grupo | C2: LOCAL | D2: VISITANTE | E2: GL | F2: GV | G2: GL | H2: GV | I2: Pts | J2: GL | K2: GV | L2: Pts | M2: GL | N2: GV | O2: Pts | P2: GL | Q2: GV | R2: Pts | S2: GL | T2: GV | U2: Pts | V2: GL | W2: GV | X2: Pts
A3: 49 | B3: A | C3: República Checa | D3: México | E3: 0 | F3: 3 | G3: 1 | H3: 2 | I3: =IF(OR($E3="",$F3=""),"",IF(OR(G3="",H3=""),"",IF(AND(G3=$E3,H3=$F3),2,IF(SIGN(G3-H3)=SIGN($E3-$F3),1,0)))) | J3: 2 | K3: 1 | L3: =IF(OR($E3="",$F3=""),"",IF(OR(J3="",K3=""),"",IF(AND(J3=$E3,K3=$F3),2,IF(SIGN(J3-K3)=SIGN($E3-$F3),1,0)))) | M3: 1 | N3: 1 | O3: =IF(OR($E3="",$F3=""),"",IF(OR(M3="",N3=""),"",IF(AND(M3=$E3,N3=$F3),2,IF(SIGN(M3-N3)=SIGN($E3-$F3),1,0)))) | P3: 0 | Q3: 2 | R3: =IF(OR($E3="",$F3=""),"",IF(OR(P3="",Q3=""),"",IF(AND(P3=$E3,Q3=$F3),2,IF(SIGN(P3-Q3)=SIGN($E3-$F3),1,0)))) | S3: 2 | T3: 1 | U3: =IF(OR($E3="",$F3=""),"",IF(OR(S3="",T3=""),"",IF(AND(S3=$E3,T3=$F3),2,IF(SIGN(S3-T3)=SIGN($E3-$F3),1,0)))) | X3: =IF(OR($E3="",$F3=""),"",IF(OR(V3="",W3=""),"",IF(AND(V3=$E3,W3=$F3),2,IF(SIGN(V3-W3)=SIGN($E3-$F3),1,0))))
A4: 50 | B4: A | C4: Sudáfrica | D4: Corea del Sur | E4: 1 | F4: 0 | G4: 1 | H4: 3 | I4: =IF(OR($E4="",$F4=""),"",IF(OR(G4="",H4=""),"",IF(AND(G4=$E4,H4=$F4),2,IF(SIGN(G4-H4)=SIGN($E4-$F4),1,0)))) | J4: 1 | K4: 2 | L4: =IF(OR($E4="",$F4=""),"",IF(OR(J4="",K4=""),"",IF(AND(J4=$E4,K4=$F4),2,IF(SIGN(J4-K4)=SIGN($E4-$F4),1,0)))) | M4: 1 | N4: 2 | O4: =IF(OR($E4="",$F4=""),"",IF(OR(M4="",N4=""),"",IF(AND(M4=$E4,N4=$F4),2,IF(SIGN(M4-N4)=SIGN($E4-$F4),1,0)))) | P4: 0 | Q4: 1 | R4: =IF(OR($E4="",$F4=""),"",IF(OR(P4="",Q4=""),"",IF(AND(P4=$E4,Q4=$F4),2,IF(SIGN(P4-Q4)=SIGN($E4-$F4),1,0)))) | S4: 1 | T4: 2 | U4: =IF(OR($E4="",$F4=""),"",IF(OR(S4="",T4=""),"",IF(AND(S4=$E4,T4=$F4),2,IF(SIGN(S4-T4)=SIGN($E4-$F4),1,0)))) | X4: =IF(OR($E4="",$F4=""),"",IF(OR(V4="",W4=""),"",IF(AND(V4=$E4,W4=$F4),2,IF(SIGN(V4-W4)=SIGN($E4-$F4),1,0))))
A5: 51 | B5: B | C5: Suiza | D5: Canadá | E5: 2 | F5: 1 | G5: 1 | H5: 0 | I5: =IF(OR($E5="",$F5=""),"",IF(OR(G5="",H5=""),"",IF(AND(G5=$E5,H5=$F5),2,IF(SIGN(G5-H5)=SIGN($E5-$F5),1,0)))) | J5: 2 | K5: 1 | L5: =IF(OR($E5="",$F5=""),"",IF(OR(J5="",K5=""),"",IF(AND(J5=$E5,K5=$F5),2,IF(SIGN(J5-K5)=SIGN($E5-$F5),1,0)))) | M5: 1 | N5: 1 | O5: =IF(OR($E5="",$F5=""),"",IF(OR(M5="",N5=""),"",IF(AND(M5=$E5,N5=$F5),2,IF(SIGN(M5-N5)=SIGN($E5-$F5),1,0)))) | P5: 1 | Q5: 1 | R5: =IF(OR($E5="",$F5=""),"",IF(OR(P5="",Q5=""),"",IF(AND(P5=$E5,Q5=$F5),2,IF(SIGN(P5-Q5)=SIGN($E5-$F5),1,0)))) | S5: 2 | T5: 1 | U5: =IF(OR($E5="",$F5=""),"",IF(OR(S5="",T5=""),"",IF(AND(S5=$E5,T5=$F5),2,IF(SIGN(S5-T5)=SIGN($E5-$F5),1,0)))) | X5: =IF(OR($E5="",$F5=""),"",IF(OR(V5="",W5=""),"",IF(AND(V5=$E5,W5=$F5),2,IF(SIGN(V5-W5)=SIGN($E5-$F5),1,0))))
A6: 52 | B6: B | C6: Bosnia y Herzegovina | D6: Catar | E6: 3 | F6: 1 | G6: 0 | H6: 1 | I6: =IF(OR($E6="",$F6=""),"",IF(OR(G6="",H6=""),"",IF(AND(G6=$E6,H6=$F6),2,IF(SIGN(G6-H6)=SIGN($E6-$F6),1,0)))) | J6: 3 | K6: 1 | L6: =IF(OR($E6="",$F6=""),"",IF(OR(J6="",K6=""),"",IF(AND(J6=$E6,K6=$F6),2,IF(SIGN(J6-K6)=SIGN($E6-$F6),1,0)))) | M6: 2 | N6: 0 | O6: =IF(OR($E6="",$F6=""),"",IF(OR(M6="",N6=""),"",IF(AND(M6=$E6,N6=$F6),2,IF(SIGN(M6-N6)=SIGN($E6-$F6),1,0)))) | P6: 2 | Q6: 0 | R6: =IF(OR($E6="",$F6=""),"",IF(OR(P6="",Q6=""),"",IF(AND(P6=$E6,Q6=$F6),2,IF(SIGN(P6-Q6)=SIGN($E6-$F6),1,0)))) | S6: 3 | T6: 1 | U6: =IF(OR($E6="",$F6=""),"",IF(OR(S6="",T6=""),"",IF(AND(S6=$E6,T6=$F6),2,IF(SIGN(S6-T6)=SIGN($E6-$F6),1,0)))) | X6: =IF(OR($E6="",$F6=""),"",IF(OR(V6="",W6=""),"",IF(AND(V6=$E6,W6=$F6),2,IF(SIGN(V6-W6)=SIGN($E6-$F6),1,0))))
A7: 53 | B7: C | C7: Escocia | D7: Brasil | E7: 0 | F7: 3 | G7: 0 | H7: 3 | I7: =IF(OR($E7="",$F7=""),"",IF(OR(G7="",H7=""),"",IF(AND(G7=$E7,H7=$F7),2,IF(SIGN(G7-H7)=SIGN($E7-$F7),1,0)))) | J7: 0 | K7: 2 | L7: =IF(OR($E7="",$F7=""),"",IF(OR(J7="",K7=""),"",IF(AND(J7=$E7,K7=$F7),2,IF(SIGN(J7-K7)=SIGN($E7-$F7),1,0)))) | M7: 0 | N7: 2 | O7: =IF(OR($E7="",$F7=""),"",IF(OR(M7="",N7=""),"",IF(AND(M7=$E7,N7=$F7),2,IF(SIGN(M7-N7)=SIGN($E7-$F7),1,0)))) | P7: 1 | Q7: 2 | R7: =IF(OR($E7="",$F7=""),"",IF(OR(P7="",Q7=""),"",IF(AND(P7=$E7,Q7=$F7),2,IF(SIGN(P7-Q7)=SIGN($E7-$F7),1,0)))) | S7: 0 | T7: 2 | U7: =IF(OR($E7="",$F7=""),"",IF(OR(S7="",T7=""),"",IF(AND(S7=$E7,T7=$F7),2,IF(SIGN(S7-T7)=SIGN($E7-$F7),1,0)))) | X7: =IF(OR($E7="",$F7=""),"",IF(OR(V7="",W7=""),"",IF(AND(V7=$E7,W7=$F7),2,IF(SIGN(V7-W7)=SIGN($E7-$F7),1,0))))
A8: 54 | B8: C | C8: Marruecos | D8: Haití | E8: 4 | F8: 2 | G8: 3 | H8: 0 | I8: =IF(OR($E8="",$F8=""),"",IF(OR(G8="",H8=""),"",IF(AND(G8=$E8,H8=$F8),2,IF(SIGN(G8-H8)=SIGN($E8-$F8),1,0)))) | J8: 2 | K8: 0 | L8: =IF(OR($E8="",$F8=""),"",IF(OR(J8="",K8=""),"",IF(AND(J8=$E8,K8=$F8),2,IF(SIGN(J8-K8)=SIGN($E8-$F8),1,0)))) | M8: 2 | N8: 0 | O8: =IF(OR($E8="",$F8=""),"",IF(OR(M8="",N8=""),"",IF(AND(M8=$E8,N8=$F8),2,IF(SIGN(M8-N8)=SIGN($E8-$F8),1,0)))) | P8: 3 | Q8: 0 | R8: =IF(OR($E8="",$F8=""),"",IF(OR(P8="",Q8=""),"",IF(AND(P8=$E8,Q8=$F8),2,IF(SIGN(P8-Q8)=SIGN($E8-$F8),1,0)))) | S8: 2 | T8: 0 | U8: =IF(OR($E8="",$F8=""),"",IF(OR(S8="",T8=""),"",IF(AND(S8=$E8,T8=$F8),2,IF(SIGN(S8-T8)=SIGN($E8-$F8),1,0)))) | X8: =IF(OR($E8="",$F8=""),"",IF(OR(V8="",W8=""),"",IF(AND(V8=$E8,W8=$F8),2,IF(SIGN(V8-W8)=SIGN($E8-$F8),1,0))))
A9: 55 | B9: D | C9: Turquía | D9: Estados Unidos | E9: 3 | F9: 2 | G9: 2 | H9: 1 | I9: =IF(OR($E9="",$F9=""),"",IF(OR(G9="",H9=""),"",IF(AND(G9=$E9,H9=$F9),2,IF(SIGN(G9-H9)=SIGN($E9-$F9),1,0)))) | J9: 0 | K9: 2 | L9: =IF(OR($E9="",$F9=""),"",IF(OR(J9="",K9=""),"",IF(AND(J9=$E9,K9=$F9),2,IF(SIGN(J9-K9)=SIGN($E9-$F9),1,0)))) | M9: 1 | N9: 1 | O9: =IF(OR($E9="",$F9=""),"",IF(OR(M9="",N9=""),"",IF(AND(M9=$E9,N9=$F9),2,IF(SIGN(M9-N9)=SIGN($E9-$F9),1,0)))) | P9: 2 | Q9: 2 | R9: =IF(OR($E9="",$F9=""),"",IF(OR(P9="",Q9=""),"",IF(AND(P9=$E9,Q9=$F9),2,IF(SIGN(P9-Q9)=SIGN($E9-$F9),1,0)))) | S9: 1 | T9: 2 | U9: =IF(OR($E9="",$F9=""),"",IF(OR(S9="",T9=""),"",IF(AND(S9=$E9,T9=$F9),2,IF(SIGN(S9-T9)=SIGN($E9-$F9),1,0)))) | X9: =IF(OR($E9="",$F9=""),"",IF(OR(V9="",W9=""),"",IF(AND(V9=$E9,W9=$F9),2,IF(SIGN(V9-W9)=SIGN($E9-$F9),1,0))))
A10: 56 | B10: D | C10: Paraguay | D10: Australia | E10: 0 | F10: 0 | G10: 1 | H10: 1 | I10: =IF(OR($E10="",$F10=""),"",IF(OR(G10="",H10=""),"",IF(AND(G10=$E10,H10=$F10),2,IF(SIGN(G10-H10)=SIGN($E10-$F10),1,0)))) | J10: 1 | K10: 2 | L10: =IF(OR($E10="",$F10=""),"",IF(OR(J10="",K10=""),"",IF(AND(J10=$E10,K10=$F10),2,IF(SIGN(J10-K10)=SIGN($E10-$F10),1,0)))) | M10: 1 | N10: 1 | O10: =IF(OR($E10="",$F10=""),"",IF(OR(M10="",N10=""),"",IF(AND(M10=$E10,N10=$F10),2,IF(SIGN(M10-N10)=SIGN($E10-$F10),1,0)))) | P10: 1 | Q10: 1 | R10: =IF(OR($E10="",$F10=""),"",IF(OR(P10="",Q10=""),"",IF(AND(P10=$E10,Q10=$F10),2,IF(SIGN(P10-Q10)=SIGN($E10-$F10),1,0)))) | S10: 1 | T10: 1 | U10: =IF(OR($E10="",$F10=""),"",IF(OR(S10="",T10=""),"",IF(AND(S10=$E10,T10=$F10),2,IF(SIGN(S10-T10)=SIGN($E10-$F10),1,0)))) | X10: =IF(OR($E10="",$F10=""),"",IF(OR(V10="",W10=""),"",IF(AND(V10=$E10,W10=$F10),2,IF(SIGN(V10-W10)=SIGN($E10-$F10),1,0))))
A11: 57 | B11: E | C11: Ecuador | D11: Alemania | E11: 2 | F11: 1 | G11: 1 | H11: 3 | I11: =IF(OR($E11="",$F11=""),"",IF(OR(G11="",H11=""),"",IF(AND(G11=$E11,H11=$F11),2,IF(SIGN(G11-H11)=SIGN($E11-$F11),1,0)))) | J11: 0 | K11: 2 | L11: =IF(OR($E11="",$F11=""),"",IF(OR(J11="",K11=""),"",IF(AND(J11=$E11,K11=$F11),2,IF(SIGN(J11-K11)=SIGN($E11-$F11),1,0)))) | M11: 1 | N11: 2 | O11: =IF(OR($E11="",$F11=""),"",IF(OR(M11="",N11=""),"",IF(AND(M11=$E11,N11=$F11),2,IF(SIGN(M11-N11)=SIGN($E11-$F11),1,0)))) | P11: 1 | Q11: 3 | R11: =IF(OR($E11="",$F11=""),"",IF(OR(P11="",Q11=""),"",IF(AND(P11=$E11,Q11=$F11),2,IF(SIGN(P11-Q11)=SIGN($E11-$F11),1,0)))) | S11: 1 | T11: 2 | U11: =IF(OR($E11="",$F11=""),"",IF(OR(S11="",T11=""),"",IF(AND(S11=$E11,T11=$F11),2,IF(SIGN(S11-T11)=SIGN($E11-$F11),1,0)))) | X11: =IF(OR($E11="",$F11=""),"",IF(OR(V11="",W11=""),"",IF(AND(V11=$E11,W11=$F11),2,IF(SIGN(V11-W11)=SIGN($E11-$F11),1,0))))
A12: 58 | B12: E | C12: Curazao | D12: Costa de Marfil | E12: 0 | F12: 2 | G12: 1 | H12: 2 | I12: =IF(OR($E12="",$F12=""),"",IF(OR(G12="",H12=""),"",IF(AND(G12=$E12,H12=$F12),2,IF(SIGN(G12-H12)=SIGN($E12-$F12),1,0)))) | J12: 0 | K12: 1 | L12: =IF(OR($E12="",$F12=""),"",IF(OR(J12="",K12=""),"",IF(AND(J12=$E12,K12=$F12),2,IF(SIGN(J12-K12)=SIGN($E12-$F12),1,0)))) | M12: 0 | N12: 2 | O12: =IF(OR($E12="",$F12=""),"",IF(OR(M12="",N12=""),"",IF(AND(M12=$E12,N12=$F12),2,IF(SIGN(M12-N12)=SIGN($E12-$F12),1,0)))) | P12: 0 | Q12: 2 | R12: =IF(OR($E12="",$F12=""),"",IF(OR(P12="",Q12=""),"",IF(AND(P12=$E12,Q12=$F12),2,IF(SIGN(P12-Q12)=SIGN($E12-$F12),1,0)))) | S12: 1 | T12: 2 | U12: =IF(OR($E12="",$F12=""),"",IF(OR(S12="",T12=""),"",IF(AND(S12=$E12,T12=$F12),2,IF(SIGN(S12-T12)=SIGN($E12-$F12),1,0)))) | X12: =IF(OR($E12="",$F12=""),"",IF(OR(V12="",W12=""),"",IF(AND(V12=$E12,W12=$F12),2,IF(SIGN(V12-W12)=SIGN($E12-$F12),1,0))))
A13: 59 | B13: F | C13: Túnez | D13: Países Bajos | E13: 1 | F13: 3 | G13: 0 | H13: 2 | I13: =IF(OR($E13="",$F13=""),"",IF(OR(G13="",H13=""),"",IF(AND(G13=$E13,H13=$F13),2,IF(SIGN(G13-H13)=SIGN($E13-$F13),1,0)))) | J13: 0 | K13: 1 | L13: =IF(OR($E13="",$F13=""),"",IF(OR(J13="",K13=""),"",IF(AND(J13=$E13,K13=$F13),2,IF(SIGN(J13-K13)=SIGN($E13-$F13),1,0)))) | M13: 0 | N13: 2 | O13: =IF(OR($E13="",$F13=""),"",IF(OR(M13="",N13=""),"",IF(AND(M13=$E13,N13=$F13),2,IF(SIGN(M13-N13)=SIGN($E13-$F13),1,0)))) | P13: 0 | Q13: 2 | R13: =IF(OR($E13="",$F13=""),"",IF(OR(P13="",Q13=""),"",IF(AND(P13=$E13,Q13=$F13),2,IF(SIGN(P13-Q13)=SIGN($E13-$F13),1,0)))) | S13: 0 | T13: 3 | U13: =IF(OR($E13="",$F13=""),"",IF(OR(S13="",T13=""),"",IF(AND(S13=$E13,T13=$F13),2,IF(SIGN(S13-T13)=SIGN($E13-$F13),1,0)))) | X13: =IF(OR($E13="",$F13=""),"",IF(OR(V13="",W13=""),"",IF(AND(V13=$E13,W13=$F13),2,IF(SIGN(V13-W13)=SIGN($E13-$F13),1,0))))
A14: 60 | B14: F | C14: Japón | D14: Suecia | E14: 1 | F14: 1 | G14: 1 | H14: 1 | I14: =IF(OR($E14="",$F14=""),"",IF(OR(G14="",H14=""),"",IF(AND(G14=$E14,H14=$F14),2,IF(SIGN(G14-H14)=SIGN($E14-$F14),1,0)))) | J14: 1 | K14: 1 | L14: =IF(OR($E14="",$F14=""),"",IF(OR(J14="",K14=""),"",IF(AND(J14=$E14,K14=$F14),2,IF(SIGN(J14-K14)=SIGN($E14-$F14),1,0)))) | M14: 2 | N14: 1 | O14: =IF(OR($E14="",$F14=""),"",IF(OR(M14="",N14=""),"",IF(AND(M14=$E14,N14=$F14),2,IF(SIGN(M14-N14)=SIGN($E14-$F14),1,0)))) | P14: 2 | Q14: 2 | R14: =IF(OR($E14="",$F14=""),"",IF(OR(P14="",Q14=""),"",IF(AND(P14=$E14,Q14=$F14),2,IF(SIGN(P14-Q14)=SIGN($E14-$F14),1,0)))) | S14: 2 | T14: 2 | U14: =IF(OR($E14="",$F14=""),"",IF(OR(S14="",T14=""),"",IF(AND(S14=$E14,T14=$F14),2,IF(SIGN(S14-T14)=SIGN($E14-$F14),1,0)))) | X14: =IF(OR($E14="",$F14=""),"",IF(OR(V14="",W14=""),"",IF(AND(V14=$E14,W14=$F14),2,IF(SIGN(V14-W14)=SIGN($E14-$F14),1,0))))
... A20: 66 | B20: I | C20: Senegal | D20: Irak | E20: 5 | F20: 0 | G20: 2 | H20: 0 | I20: =IF(OR($E20="",$F20=""),"",IF(OR(G20="",H20=""),"",IF(AND(G20=$E20,H20=$F20),2,IF(SIGN(G20-H20)=SIGN($E20-$F20),1,0)))) | J20: 1 | K20: 1 | L20: =IF(OR($E20="",$F20=""),"",IF(OR(J20="",K20=""),"",IF(AND(J20=$E20,K20=$F20),2,IF(SIGN(J20-K20)=SIGN($E20-$F20),1,0)))) | M20: 2 | N20: 0 | O20: =IF(OR($E20="",$F20=""),"",IF(OR(M20="",N20=""),"",IF(AND(M20=$E20,N20=$F20),2,IF(SIGN(M20-N20)=SIGN($E20-$F20),1,0)))) | P20: 2 | Q20: 0 | R20: =IF(OR($E20="",$F20=""),"",IF(OR(P20="",Q20=""),"",IF(AND(P20=$E20,Q20=$F20),2,IF(SIGN(P20-Q20)=SIGN($E20-$F20),1,0)))) | S20: 2 | T20: 1 | U20: =IF(OR($E20="",$F20=""),"",IF(OR(S20="",T20=""),"",IF(AND(S20=$E20,T20=$F20),2,IF(SIGN(S20-T20)=SIGN($E20-$F20),1,0)))) | X20: =IF(OR($E20="",$F20=""),"",IF(OR(V20="",W20=""),"",IF(AND(V20=$E20,W20=$F20),2,IF(SIGN(V20-W20)=SIGN($E20-$F20),1,0))))
A21: 67 | B21: J | C21: Jordania | D21: Argentina | E21: 1 | F21: 3 | G21: 0 | H21: 2 | I21: =IF(OR($E21="",$F21=""),"",IF(OR(G21="",H21=""),"",IF(AND(G21=$E21,H21=$F21),2,IF(SIGN(G21-H21)=SIGN($E21-$F21),1,0)))) | L21: =IF(OR($E21="",$F21=""),"",IF(OR(J21="",K21=""),"",IF(AND(J21=$E21,K21=$F21),2,IF(SIGN(J21-K21)=SIGN($E21-$F21),1,0)))) | M21: 0 | N21: 3 | O21: =IF(OR($E21="",$F21=""),"",IF(OR(M21="",N21=""),"",IF(AND(M21=$E21,N21=$F21),2,IF(SIGN(M21-N21)=SIGN($E21-$F21),1,0)))) | P21: 0 | Q21: 5 | R21: =IF(OR($E21="",$F21=""),"",IF(OR(P21="",Q21=""),"",IF(AND(P21=$E21,Q21=$F21),2,IF(SIGN(P21-Q21)=SIGN($E21-$F21),1,0)))) | S21: 0 | T21: 3 | U21: =IF(OR($E21="",$F21=""),"",IF(OR(S21="",T21=""),"",IF(AND(S21=$E21,T21=$F21),2,IF(SIGN(S21-T21)=SIGN($E21-$F21),1,0)))) | X21: =IF(OR($E21="",$F21=""),"",IF(OR(V21="",W21=""),"",IF(AND(V21=$E21,W21=$F21),2,IF(SIGN(V21-W21)=SIGN($E21-$F21),1,0))))
A22: 68 | B22: J | C22: Argelia | D22: Austria | E22: 3 | F22: 3 | G22: 0 | H22: 1 | I22: =IF(OR($E22="",$F22=""),"",IF(OR(G22="",H22=""),"",IF(AND(G22=$E22,H22=$F22),2,IF(SIGN(G22-H22)=SIGN($E22-$F22),1,0)))) | L22: =IF(OR($E22="",$F22=""),"",IF(OR(J22="",K22=""),"",IF(AND(J22=$E22,K22=$F22),2,IF(SIGN(J22-K22)=SIGN($E22-$F22),1,0)))) | M22: 1 | N22: 1 | O22: =IF(OR($E22="",$F22=""),"",IF(OR(M22="",N22=""),"",IF(AND(M22=$E22,N22=$F22),2,IF(SIGN(M22-N22)=SIGN($E22-$F22),1,0)))) | P22: 2 | Q22: 2 | R22: =IF(OR($E22="",$F22=""),"",IF(OR(P22="",Q22=""),"",IF(AND(P22=$E22,Q22=$F22),2,IF(SIGN(P22-Q22)=SIGN($E22-$F22),1,0)))) | S22: 1 | T22: 1 | U22: =IF(OR($E22="",$F22=""),"",IF(OR(S22="",T22=""),"",IF(AND(S22=$E22,T22=$F22),2,IF(SIGN(S22-T22)=SIGN($E22-$F22),1,0)))) | X22: =IF(OR($E22="",$F22=""),"",IF(OR(V22="",W22=""),"",IF(AND(V22=$E22,W22=$F22),2,IF(SIGN(V22-W22)=SIGN($E22-$F22),1,0))))
A23: 69 | B23: K | C23: Colombia | D23: Portugal | E23: 0 | F23: 0 | G23: 1 | H23: 2 | I23: =IF(OR($E23="",$F23=""),"",IF(OR(G23="",H23=""),"",IF(AND(G23=$E23,H23=$F23),2,IF(SIGN(G23-H23)=SIGN($E23-$F23),1,0)))) | L23: =IF(OR($E23="",$F23=""),"",IF(OR(J23="",K23=""),"",IF(AND(J23=$E23,K23=$F23),2,IF(SIGN(J23-K23)=SIGN($E23-$F23),1,0)))) | M23: 1 | N23: 2 | O23: =IF(OR($E23="",$F23=""),"",IF(OR(M23="",N23=""),"",IF(AND(M23=$E23,N23=$F23),2,IF(SIGN(M23-N23)=SIGN($E23-$F23),1,0)))) | P23: 1 | Q23: 2 | R23: =IF(OR($E23="",$F23=""),"",IF(OR(P23="",Q23=""),"",IF(AND(P23=$E23,Q23=$F23),2,IF(SIGN(P23-Q23)=SIGN($E23-$F23),1,0)))) | S23: 2 | T23: 2 | U23: =IF(OR($E23="",$F23=""),"",IF(OR(S23="",T23=""),"",IF(AND(S23=$E23,T23=$F23),2,IF(SIGN(S23-T23)=SIGN($E23-$F23),1,0)))) | X23: =IF(OR($E23="",$F23=""),"",IF(OR(V23="",W23=""),"",IF(AND(V23=$E23,W23=$F23),2,IF(SIGN(V23-W23)=SIGN($E23-$F23),1,0))))
A24: 70 | B24: K | C24: RD Congo | D24: Uzbekistán | E24: 3 | F24: 1 | G24: 0 | H24: 0 | I24: =IF(OR($E24="",$F24=""),"",IF(OR(G24="",H24=""),"",IF(AND(G24=$E24,H24=$F24),2,IF(SIGN(G24-H24)=SIGN($E24-$F24),1,0)))) | L24: =IF(OR($E24="",$F24=""),"",IF(OR(J24="",K24=""),"",IF(AND(J24=$E24,K24=$F24),2,IF(SIGN(J24-K24)=SIGN($E24-$F24),1,0)))) | M24: 1 | N24: 1 | O24: =IF(OR($E24="",$F24=""),"",IF(OR(M24="",N24=""),"",IF(AND(M24=$E24,N24=$F24),2,IF(SIGN(M24-N24)=SIGN($E24-$F24),1,0)))) | P24: 1 | Q24: 1 | R24: =IF(OR($E24="",$F24=""),"",IF(OR(P24="",Q24=""),"",IF(AND(P24=$E24,Q24=$F24),2,IF(SIGN(P24-Q24)=SIGN($E24-$F24),1,0)))) | S24: 2 | T24: 1 | U24: =IF(OR($E24="",$F24=""),"",IF(OR(S24="",T24=""),"",IF(AND(S24=$E24,T24=$F24),2,IF(SIGN(S24-T24)=SIGN($E24-$F24),1,0)))) | X24: =IF(OR($E24="",$F24=""),"",IF(OR(V24="",W24=""),"",IF(AND(V24=$E24,W24=$F24),2,IF(SIGN(V24-W24)=SIGN($E24-$F24),1,0))))
A25: 71 | B25: L | C25: Panamá | D25: Inglaterra | E25: 0 | F25: 2 | G25: 1 | H25: 4 | I25: =IF(OR($E25="",$F25=""),"",IF(OR(G25="",H25=""),"",IF(AND(G25=$E25,H25=$F25),2,IF(SIGN(G25-H25)=SIGN($E25-$F25),1,0)))) | L25: =IF(OR($E25="",$F25=""),"",IF(OR(J25="",K25=""),"",IF(AND(J25=$E25,K25=$F25),2,IF(SIGN(J25-K25)=SIGN($E25-$F25),1,0)))) | M25: 0 | N25: 3 | O25: =IF(OR($E25="",$F25=""),"",IF(OR(M25="",N25=""),"",IF(AND(M25=$E25,N25=$F25),2,IF(SIGN(M25-N25)=SIGN($E25-$F25),1,0)))) | P25: 0 | Q25: 4 | R25: =IF(OR($E25="",$F25=""),"",IF(OR(P25="",Q25=""),"",IF(AND(P25=$E25,Q25=$F25),2,IF(SIGN(P25-Q25)=SIGN($E25-$F25),1,0)))) | S25: 0 | T25: 3 | U25: =IF(OR($E25="",$F25=""),"",IF(OR(S25="",T25=""),"",IF(AND(S25=$E25,T25=$F25),2,IF(SIGN(S25-T25)=SIGN($E25-$F25),1,0)))) | X25: =IF(OR($E25="",$F25=""),"",IF(OR(V25="",W25=""),"",IF(AND(V25=$E25,W25=$F25),2,IF(SIGN(V25-W25)=SIGN($E25-$F25),1,0))))
A26: 72 | B26: L | C26: Croacia | D26: Ghana | E26: 2 | F26: 1 | I26: =IF(OR($E26="",$F26=""),"",IF(OR(G26="",H26=""),"",IF(AND(G26=$E26,H26=$F26),2,IF(SIGN(G26-H26)=SIGN($E26-$F26),1,0)))) | L26: =IF(OR($E26="",$F26=""),"",IF(OR(J26="",K26=""),"",IF(AND(J26=$E26,K26=$F26),2,IF(SIGN(J26-K26)=SIGN($E26-$F26),1,0)))) | M26: 2 | N26: 0 | O26: =IF(OR($E26="",$F26=""),"",IF(OR(M26="",N26=""),"",IF(AND(M26=$E26,N26=$F26),2,IF(SIGN(M26-N26)=SIGN($E26-$F26),1,0)))) | P26: 2 | Q26: 1 | R26: =IF(OR($E26="",$F26=""),"",IF(OR(P26="",Q26=""),"",IF(AND(P26=$E26,Q26=$F26),2,IF(SIGN(P26-Q26)=SIGN($E26-$F26),1,0)))) | S26: 2 | T26: 1 | U26: =IF(OR($E26="",$F26=""),"",IF(OR(S26="",T26=""),"",IF(AND(S26=$E26,T26=$F26),2,IF(SIGN(S26-T26)=SIGN($E26-$F26),1,0)))) | X26: =IF(OR($E26="",$F26=""),"",IF(OR(V26="",W26=""),"",IF(AND(V26=$E26,W26=$F26),2,IF(SIGN(V26-W26)=SIGN($E26-$F26),1,0))))
D27: PUNTOS JORNADA | I27: =SUM(I3:I26) | L27: =SUM(L3:L26) | O27: =SUM(O3:O26) | R27: =SUM(R3:R26) | U27: =SUM(U3:U26) | X27: =SUM(X3:X26)

Sheet 32avos
A1: PARTIDO | E1: RESULTADO REAL | G1: Jugador 1 | J1: Jugador 2 | M1: Jugador 3 | P1: Jugador 4 | S1: Jugador 5 | V1: Jugador 6
A2: Nº | B2: Grupo | C2: LOCAL | D2: VISITANTE | E2: GL | F2: GV | G2: GL | H2: GV | I2: Pts | J2: GL | K2: GV | L2: Pts | M2: GL | N2: GV | O2: Pts | P2: GL | Q2: GV | R2: Pts | S2: GL | T2: GV | U2: Pts | V2: GL | W2: GV | X2: Pts
A3: 73 | C3: Sudáfrica | D3: Canadá | E3: 0 | F3: 1 | G3: 1 | H3: 2 | I3: =IF(OR($E3="",$F3=""),"",IF(OR(G3="",H3=""),"",IF(AND(G3=$E3,H3=$F3),2,IF(SIGN(G3-H3)=SIGN($E3-$F3),1,0)))) | J3: 1 | K3: 2 | L3: =IF(OR($E3="",$F3=""),"",IF(OR(J3="",K3=""),"",IF(AND(J3=$E3,K3=$F3),2,IF(SIGN(J3-K3)=SIGN($E3-$F3),1,0)))) | M3: 1 | N3: 2 | O3: =IF(OR($E3="",$F3=""),"",IF(OR(M3="",N3=""),"",IF(AND(M3=$E3,N3=$F3),2,IF(SIGN(M3-N3)=SIGN($E3-$F3),1,0)))) | P3: 0 | Q3: 1 | R3: =IF(OR($E3="",$F3=""),"",IF(OR(P3="",Q3=""),"",IF(AND(P3=$E3,Q3=$F3),2,IF(SIGN(P3-Q3)=SIGN($E3-$F3),1,0)))) | S3: 1 | T3: 2 | U3: =IF(OR($E3="",$F3=""),"",IF(OR(S3="",T3=""),"",IF(AND(S3=$E3,T3=$F3),2,IF(SIGN(S3-T3)=SIGN($E3-$F3),1,0)))) | V3: 1 | W3: 1 | X3: =IF(OR($E3="",$F3=""),"",IF(OR(V3="",W3=""),"",IF(AND(V3=$E3,W3=$F3),2,IF(SIGN(V3-W3)=SIGN($E3-$F3),1,0))))
A4: 74 | C4: Alemania | D4: Paraguay | E4: 1 | F4: 1 | G4: 3 | H4: 0 | I4: =IF(OR($E4="",$F4=""),"",IF(OR(G4="",H4=""),"",IF(AND(G4=$E4,H4=$F4),2,IF(SIGN(G4-H4)=SIGN($E4-$F4),1,0)))) | J4: 2 | K4: 0 | L4: =IF(OR($E4="",$F4=""),"",IF(OR(J4="",K4=""),"",IF(AND(J4=$E4,K4=$F4),2,IF(SIGN(J4-K4)=SIGN($E4-$F4),1,0)))) | M4: 3 | N4: 0 | O4: =IF(OR($E4="",$F4=""),"",IF(OR(M4="",N4=""),"",IF(AND(M4=$E4,N4=$F4),2,IF(SIGN(M4-N4)=SIGN($E4-$F4),1,0)))) | P4: 2 | Q4: 0 | R4: =IF(OR($E4="",$F4=""),"",IF(OR(P4="",Q4=""),"",IF(AND(P4=$E4,Q4=$F4),2,IF(SIGN(P4-Q4)=SIGN($E4-$F4),1,0)))) | S4: 3 | T4: 1 | U4: =IF(OR($E4="",$F4=""),"",IF(OR(S4="",T4=""),"",IF(AND(S4=$E4,T4=$F4),2,IF(SIGN(S4-T4)=SIGN($E4-$F4),1,0)))) | V4: 3 | W4: 0 | X4: =IF(OR($E4="",$F4=""),"",IF(OR(V4="",W4=""),"",IF(AND(V4=$E4,W4=$F4),2,IF(SIGN(V4-W4)=SIGN($E4-$F4),1,0))))
A5: 75 | C5: Países Bajos | D5: Marruecos | E5: 1 | F5: 1 | G5: 2 | H5: 1 | I5: =IF(OR($E5="",$F5=""),"",IF(OR(G5="",H5=""),"",IF(AND(G5=$E5,H5=$F5),2,IF(SIGN(G5-H5)=SIGN($E5-$F5),1,0)))) | J5: 2 | K5: 1 | L5: =IF(OR($E5="",$F5=""),"",IF(OR(J5="",K5=""),"",IF(AND(J5=$E5,K5=$F5),2,IF(SIGN(J5-K5)=SIGN($E5-$F5),1,0)))) | M5: 1 | N5: 1 | O5: =IF(OR($E5="",$F5=""),"",IF(OR(M5="",N5=""),"",IF(AND(M5=$E5,N5=$F5),2,IF(SIGN(M5-N5)=SIGN($E5-$F5),1,0)))) | P5: 1 | Q5: 2 | R5: =IF(OR($E5="",$F5=""),"",IF(OR(P5="",Q5=""),"",IF(AND(P5=$E5,Q5=$F5),2,IF(SIGN(P5-Q5)=SIGN($E5-$F5),1,0)))) | S5: 2 | T5: 1 | U5: =IF(OR($E5="",$F5=""),"",IF(OR(S5="",T5=""),"",IF(AND(S5=$E5,T5=$F5),2,IF(SIGN(S5-T5)=SIGN($E5-$F5),1,0)))) | V5: 2 | W5: 0 | X5: =IF(OR($E5="",$F5=""),"",IF(OR(V5="",W5=""),"",IF(AND(V5=$E5,W5=$F5),2,IF(SIGN(V5-W5)=SIGN($E5-$F5),1,0))))
A6: 76 | C6: Brasil | D6: Japón | E6: 2 | F6: 1 | G6: 3 | H6: 1 | I6: =IF(OR($E6="",$F6=""),"",IF(OR(G6="",H6=""),"",IF(AND(G6=$E6,H6=$F6),2,IF(SIGN(G6-H6)=SIGN($E6-$F6),1,0)))) | J6: 2 | K6: 1 | L6: =IF(OR($E6="",$F6=""),"",IF(OR(J6="",K6=""),"",IF(AND(J6=$E6,K6=$F6),2,IF(SIGN(J6-K6)=SIGN($E6-$F6),1,0)))) | M6: 2 | N6: 0 | O6: =IF(OR($E6="",$F6=""),"",IF(OR(M6="",N6=""),"",IF(AND(M6=$E6,N6=$F6),2,IF(SIGN(M6-N6)=SIGN($E6-$F6),1,0)))) | P6: 1 | Q6: 0 | R6: =IF(OR($E6="",$F6=""),"",IF(OR(P6="",Q6=""),"",IF(AND(P6=$E6,Q6=$F6),2,IF(SIGN(P6-Q6)=SIGN($E6-$F6),1,0)))) | S6: 2 | T6: 2 | U6: =IF(OR($E6="",$F6=""),"",IF(OR(S6="",T6=""),"",IF(AND(S6=$E6,T6=$F6),2,IF(SIGN(S6-T6)=SIGN($E6-$F6),1,0)))) | V6: 2 | W6: 1 | X6: =IF(OR($E6="",$F6=""),"",IF(OR(V6="",W6=""),"",IF(AND(V6=$E6,W6=$F6),2,IF(SIGN(V6-W6)=SIGN($E6-$F6),1,0))))
A7: 77 | C7: Francia | D7: Suecia | E7: 3 | F7: 0 | G7: 2 | H7: 0 | I7: =IF(OR($E7="",$F7=""),"",IF(OR(G7="",H7=""),"",IF(AND(G7=$E7,H7=$F7),2,IF(SIGN(G7-H7)=SIGN($E7-$F7),1,0)))) | J7: 2 | K7: 0 | L7: =IF(OR($E7="",$F7=""),"",IF(OR(J7="",K7=""),"",IF(AND(J7=$E7,K7=$F7),2,IF(SIGN(J7-K7)=SIGN($E7-$F7),1,0)))) | M7: 2 | N7: 1 | O7: =IF(OR($E7="",$F7=""),"",IF(OR(M7="",N7=""),"",IF(AND(M7=$E7,N7=$F7),2,IF(SIGN(M7-N7)=SIGN($E7-$F7),1,0)))) | P7: 1 | Q7: 0 | R7: =IF(OR($E7="",$F7=""),"",IF(OR(P7="",Q7=""),"",IF(AND(P7=$E7,Q7=$F7),2,IF(SIGN(P7-Q7)=SIGN($E7-$F7),1,0)))) | S7: 3 | T7: 1 | U7: =IF(OR($E7="",$F7=""),"",IF(OR(S7="",T7=""),"",IF(AND(S7=$E7,T7=$F7),2,IF(SIGN(S7-T7)=SIGN($E7-$F7),1,0)))) | V7: 3 | W7: 0 | X7: =IF(OR($E7="",$F7=""),"",IF(OR(V7="",W7=""),"",IF(AND(V7=$E7,W7=$F7),2,IF(SIGN(V7-W7)=SIGN($E7-$F7),1,0))))
A8: 78 | C8: Costa de Marfil | D8: Noruega | E8: 1 | F8: 2 | G8: 1 | H8: 2 | I8: =IF(OR($E8="",$F8=""),"",IF(OR(G8="",H8=""),"",IF(AND(G8=$E8,H8=$F8),2,IF(SIGN(G8-H8)=SIGN($E8-$F8),1,0)))) | J8: 0 | K8: 2 | L8: =IF(OR($E8="",$F8=""),"",IF(OR(J8="",K8=""),"",IF(AND(J8=$E8,K8=$F8),2,IF(SIGN(J8-K8)=SIGN($E8-$F8),1,0)))) | M8: 1 | N8: 1 | O8: =IF(OR($E8="",$F8=""),"",IF(OR(M8="",N8=""),"",IF(AND(M8=$E8,N8=$F8),2,IF(SIGN(M8-N8)=SIGN($E8-$F8),1,0)))) | P8: 0 | Q8: 2 | R8: =IF(OR($E8="",$F8=""),"",IF(OR(P8="",Q8=""),"",IF(AND(P8=$E8,Q8=$F8),2,IF(SIGN(P8-Q8)=SIGN($E8-$F8),1,0)))) | S8: 1 | T8: 2 | U8: =IF(OR($E8="",$F8=""),"",IF(OR(S8="",T8=""),"",IF(AND(S8=$E8,T8=$F8),2,IF(SIGN(S8-T8)=SIGN($E8-$F8),1,0)))) | V8: 0 | W8: 2 | X8: =IF(OR($E8="",$F8=""),"",IF(OR(V8="",W8=""),"",IF(AND(V8=$E8,W8=$F8),2,IF(SIGN(V8-W8)=SIGN($E8-$F8),1,0))))
A9: 79 | C9: México | D9: Ecuador | E9: 2 | F9: 0 | G9: 3 | H9: 1 | I9: =IF(OR($E9="",$F9=""),"",IF(OR(G9="",H9=""),"",IF(AND(G9=$E9,H9=$F9),2,IF(SIGN(G9-H9)=SIGN($E9-$F9),1,0)))) | J9: 1 | K9: 1 | L9: =IF(OR($E9="",$F9=""),"",IF(OR(J9="",K9=""),"",IF(AND(J9=$E9,K9=$F9),2,IF(SIGN(J9-K9)=SIGN($E9-$F9),1,0)))) | M9: 1 | N9: 2 | O9: =IF(OR($E9="",$F9=""),"",IF(OR(M9="",N9=""),"",IF(AND(M9=$E9,N9=$F9),2,IF(SIGN(M9-N9)=SIGN($E9-$F9),1,0)))) | P9: 1 | Q9: 0 | R9: =IF(OR($E9="",$F9=""),"",IF(OR(P9="",Q9=""),"",IF(AND(P9=$E9,Q9=$F9),2,IF(SIGN(P9-Q9)=SIGN($E9-$F9),1,0)))) | S9: 1 | T9: 1 | U9: =IF(OR($E9="",$F9=""),"",IF(OR(S9="",T9=""),"",IF(AND(S9=$E9,T9=$F9),2,IF(SIGN(S9-T9)=SIGN($E9-$F9),1,0)))) | V9: 2 | W9: 1 | X9: =IF(OR($E9="",$F9=""),"",IF(OR(V9="",W9=""),"",IF(AND(V9=$E9,W9=$F9),2,IF(SIGN(V9-W9)=SIGN($E9-$F9),1,0))))
A10: 80 | C10: Inglaterra | D10: RD Congo | E10: 2 | F10: 1 | G10: 4 | H10: 0 | I10: =IF(OR($E10="",$F10=""),"",IF(OR(G10="",H10=""),"",IF(AND(G10=$E10,H10=$F10),2,IF(SIGN(G10-H10)=SIGN($E10-$F10),1,0)))) | J10: 2 | K10: 0 | L10: =IF(OR($E10="",$F10=""),"",IF(OR(J10="",K10=""),"",IF(AND(J10=$E10,K10=$F10),2,IF(SIGN(J10-K10)=SIGN($E10-$F10),1,0)))) | M10: 3 | N10: 0 | O10: =IF(OR($E10="",$F10=""),"",IF(OR(M10="",N10=""),"",IF(AND(M10=$E10,N10=$F10),2,IF(SIGN(M10-N10)=SIGN($E10-$F10),1,0)))) | P10: 2 | Q10: 0 | R10: =IF(OR($E10="",$F10=""),"",IF(OR(P10="",Q10=""),"",IF(AND(P10=$E10,Q10=$F10),2,IF(SIGN(P10-Q10)=SIGN($E10-$F10),1,0)))) | S10: 2 | T10: 0 | U10: =IF(OR($E10="",$F10=""),"",IF(OR(S10="",T10=""),"",IF(AND(S10=$E10,T10=$F10),2,IF(SIGN(S10-T10)=SIGN($E10-$F10),1,0)))) | V10: 2 | W10: 0 | X10: =IF(OR($E10="",$F10=""),"",IF(OR(V10="",W10=""),"",IF(AND(V10=$E10,W10=$F10),2,IF(SIGN(V10-W10)=SIGN($E10-$F10),1,0))))
